<mujoco model="pm_mll">
  <compiler settotalmass="50.0"/>
  <default>
    <default class="/"/>
    <default class="left_leg/"/>
    <default class="right_leg/"/>
  </default>
  <asset>
    <texture name="texplane" type="2d" builtin="checker" rgb1="0.20000000000000001 0.20000000000000001 0.20000000000000001" rgb2="0.29999999999999999 0.29999999999999999 0.29999999999999999" width="512" height="512"/>
    <material name="grid" class="/" texture="texplane" texrepeat="1 1" texuniform="true" reflectance="0.0"/>
  </asset>
  <worldbody>
    <geom name="floor" class="/" type="plane" conaffinity="1" size="100 100 0.20000000000000001" material="grid" pos="0 0 0"/>
    <body name="torso" pos="0 0 0.67100000000000004">
      <light name="top" class="/" mode="trackcom" pos="0 0 2"/>
      <camera name="back" class="/" mode="trackcom" pos="-3 0 1" xyaxes="0 -1 0 1 0 2"/>
      <camera name="side" class="/" mode="trackcom" pos="0 -3 1" xyaxes="1 0 0 0 1 2"/>
      <freejoint name="root"/>
      <geom name="head" class="/" type="sphere" size="0.10000000000000001" pos="0 0 0"/>
      <site name="com" class="/" type="sphere" rgba="1 0 0 1" size="0.01" pos="0 0 0"/>
      <camera name="egocentric" class="/" fovy="80.0" pos="0.089999999999999997 0 0" xyaxes="0 -1 0 0.10000000000000001 1 2"/>
      <site name="LASI" class="/" type="sphere" rgba="1 0 0 1" size="0.01" pos="0.048943999880708008 0.10500000000000001 0.057850884871788529"/>
      <site name="LPSI" class="/" type="sphere" rgba="1 0 0 1" size="0.01" pos="-0.066488008791476927 0.021000000000000001 0.0996938565740315"/>
      <site name="RASI" class="/" type="sphere" rgba="1 0 0 1" size="0.01" pos="0.048943999880708008 -0.10500000000000001 0.057850884871788529"/>
      <site name="RPSI" class="/" type="sphere" rgba="1 0 0 1" size="0.01" pos="-0.066488008791476927 -0.021000000000000001 0.0996938565740315"/>
      <site name="left_leg_site" class="/" size="9.9999999999999995e-07 9.9999999999999995e-07 9.9999999999999995e-07" pos="0 0.10000000000000001 0"/>
      <body pos="0 0.10000000000000001 0" name="left_leg/">
        <body name="left_leg/thigh">
          <joint name="left_leg/hip_x" class="left_leg/" type="hinge" axis="1 0 0" limited="true" solimplimit="0 0.98999999999999999 0.01" range="-25 5"/>
          <joint name="left_leg/hip_y" class="left_leg/" type="hinge" axis="0 1 0" limited="true" solimplimit="0 0.98999999999999999 0.01" range="-110 20"/>
          <geom name="left_leg/thigh" class="left_leg/" type="capsule" size="0.059999999999999998" mass="1e-06" fromto="0 0 0 0 0 -0.28000000000000003"/>
          <site name="left_leg/LGT" class="left_leg/" type="sphere" rgba="1 0 0 1" size="0.01" pos="0.038567256581192359 0.045962666587138677 0"/>
          <site name="left_leg/LT1" class="left_leg/" type="sphere" rgba="1 0 0 1" size="0.01" pos="0.059999999999999998 0 -0.098000000000000004"/>
          <site name="left_leg/LT2" class="left_leg/" type="sphere" rgba="1 0 0 1" size="0.01" pos="0.051961524227066319 0.029999999999999995 -0.14000000000000001"/>
          <site name="left_leg/LT3" class="left_leg/" type="sphere" rgba="1 0 0 1" size="0.01" pos="0.059999999999999998 0 -0.18200000000000002"/>
          <site name="left_leg/LT4" class="left_leg/" type="sphere" rgba="1 0 0 1" size="0.01" pos="0.051961524227066319 -0.029999999999999995 -0.14000000000000001"/>
          <body name="left_leg/shin" pos="0 0 -0.34300000000000003">
            <joint name="left_leg/knee" class="left_leg/" type="hinge" pos="0 0 0.02" axis="0 -1 0" limited="true" solimplimit="0 0.98999999999999999 0.01" stiffness="0.0" range="-160 2" armature="0.01" damping="0.0"/>
            <geom name="left_leg/shin" class="left_leg/" type="capsule" size="0.049000000000000002" mass="1e-06" fromto="0 0 0 0 0 -0.20199999999999999"/>
            <site name="left_leg/LANL" class="left_leg/" type="sphere" rgba="1 0 0 1" size="0.01" pos="3.0003846579110156e-18 0.049000000000000002 -0.20199999999999999"/>
            <site name="left_leg/LANM" class="left_leg/" type="sphere" rgba="1 0 0 1" size="0.01" pos="-9.0011539737330462e-18 -0.049000000000000002 -0.20199999999999999"/>
            <site name="left_leg/LKNL" class="left_leg/" type="sphere" rgba="1 0 0 1" size="0.01" pos="3.0003846579110156e-18 0.049000000000000002 0"/>
            <site name="left_leg/LKNM" class="left_leg/" type="sphere" rgba="1 0 0 1" size="0.01" pos="-9.0011539737330462e-18 -0.049000000000000002 0"/>
            <site name="left_leg/LS1" class="left_leg/" type="sphere" rgba="1 0 0 1" size="0.01" pos="0.049000000000000002 0 -0.070699999999999999"/>
            <site name="left_leg/LS2" class="left_leg/" type="sphere" rgba="1 0 0 1" size="0.01" pos="0.042435244785437497 0.024499999999999997 -0.10099999999999999"/>
            <site name="left_leg/LS3" class="left_leg/" type="sphere" rgba="1 0 0 1" size="0.01" pos="0.049000000000000002 0 -0.1313"/>
            <site name="left_leg/LS4" class="left_leg/" type="sphere" rgba="1 0 0 1" size="0.01" pos="0.042435244785437497 -0.024499999999999997 -0.10099999999999999"/>
            <body name="left_leg/foot" pos="0 0 -0.23199999999999996">
              <geom name="left_leg/foot" class="left_leg/" type="sphere" size="0.029999999999999999" mass="0.1" pos="0 0 0"/>
              <site name="left_leg/foot" class="left_leg/" type="sphere" rgba="1 0 0 1" size="0.01" pos="0 0 0"/>
            </body>
          </body>
        </body>
      </body>
      <site name="right_leg_site" class="/" size="9.9999999999999995e-07 9.9999999999999995e-07 9.9999999999999995e-07" pos="0 -0.10000000000000001 0"/>
      <body pos="0 -0.10000000000000001 0" name="right_leg/">
        <body name="right_leg/thigh">
          <joint name="right_leg/hip_x" class="right_leg/" type="hinge" axis="1 0 0" limited="true" solimplimit="0 0.98999999999999999 0.01" range="-25 5"/>
          <joint name="right_leg/hip_y" class="right_leg/" type="hinge" axis="0 1 0" limited="true" solimplimit="0 0.98999999999999999 0.01" range="-110 20"/>
          <geom name="right_leg/thigh" class="right_leg/" type="capsule" size="0.059999999999999998" mass="1e-06" fromto="0 0 0 0 0 -0.28000000000000003"/>
          <site name="right_leg/RGT" class="right_leg/" type="sphere" rgba="1 0 0 1" size="0.01" pos="0.038567256581192352 -0.045962666587138684 0"/>
          <site name="right_leg/RT1" class="right_leg/" type="sphere" rgba="1 0 0 1" size="0.01" pos="0.059999999999999998 0 -0.098000000000000004"/>
          <site name="right_leg/RT2" class="right_leg/" type="sphere" rgba="1 0 0 1" size="0.01" pos="0.051961524227066319 0.029999999999999995 -0.14000000000000001"/>
          <site name="right_leg/RT3" class="right_leg/" type="sphere" rgba="1 0 0 1" size="0.01" pos="0.059999999999999998 0 -0.18200000000000002"/>
          <site name="right_leg/RT4" class="right_leg/" type="sphere" rgba="1 0 0 1" size="0.01" pos="0.051961524227066319 -0.029999999999999995 -0.14000000000000001"/>
          <body name="right_leg/shin" pos="0 0 -0.34300000000000003">
            <joint name="right_leg/knee" class="right_leg/" type="hinge" pos="0 0 0.02" axis="0 -1 0" limited="true" solimplimit="0 0.98999999999999999 0.01" stiffness="0.0" range="-160 2" armature="0.01" damping="0.0"/>
            <geom name="right_leg/shin" class="right_leg/" type="capsule" size="0.049000000000000002" mass="1e-06" fromto="0 0 0 0 0 -0.20199999999999999"/>
            <site name="right_leg/RANL" class="right_leg/" type="sphere" rgba="1 0 0 1" size="0.01" pos="3.0003846579110156e-18 0.049000000000000002 -0.20199999999999999"/>
            <site name="right_leg/RANM" class="right_leg/" type="sphere" rgba="1 0 0 1" size="0.01" pos="-9.0011539737330462e-18 -0.049000000000000002 -0.20199999999999999"/>
            <site name="right_leg/RKNL" class="right_leg/" type="sphere" rgba="1 0 0 1" size="0.01" pos="-9.0011539737330462e-18 -0.049000000000000002 0"/>
            <site name="right_leg/RKNM" class="right_leg/" type="sphere" rgba="1 0 0 1" size="0.01" pos="3.0003846579110156e-18 0.049000000000000002 0"/>
            <site name="right_leg/RS1" class="right_leg/" type="sphere" rgba="1 0 0 1" size="0.01" pos="0.049000000000000002 0 -0.070699999999999999"/>
            <site name="right_leg/RS2" class="right_leg/" type="sphere" rgba="1 0 0 1" size="0.01" pos="0.042435244785437497 0.024499999999999997 -0.10099999999999999"/>
            <site name="right_leg/RS3" class="right_leg/" type="sphere" rgba="1 0 0 1" size="0.01" pos="0.049000000000000002 0 -0.1313"/>
            <site name="right_leg/RS4" class="right_leg/" type="sphere" rgba="1 0 0 1" size="0.01" pos="0.042435244785437497 -0.024499999999999997 -0.10099999999999999"/>
            <body name="right_leg/foot" pos="0 0 -0.23199999999999996">
              <geom name="right_leg/foot" class="right_leg/" type="sphere" size="0.029999999999999999" mass="0.1" pos="0 0 0"/>
              <site name="right_leg/foot" class="right_leg/" type="sphere" rgba="1 0 0 1" size="0.01" pos="0 0 0"/>
            </body>
          </body>
        </body>
      </body>
    </body>
    <body name="m0" mocap="true" pos="0 0 0">
      <geom name="m0" class="/" type="sphere" size="0.01" rgba="0 1 0 1" mass="0.0"/>
    </body>
    <body name="m1" mocap="true" pos="0 0 0">
      <geom name="m1" class="/" type="sphere" size="0.01" rgba="0 1 0 1" mass="0.0"/>
    </body>
    <body name="m2" mocap="true" pos="0 0 0">
      <geom name="m2" class="/" type="sphere" size="0.01" rgba="0 1 0 1" mass="0.0"/>
    </body>
    <body name="m3" mocap="true" pos="0 0 0">
      <geom name="m3" class="/" type="sphere" size="0.01" rgba="0 1 0 1" mass="0.0"/>
    </body>
    <body name="m4" mocap="true" pos="0 0 0">
      <geom name="m4" class="/" type="sphere" size="0.01" rgba="0 1 0 1" mass="0.0"/>
    </body>
    <body name="m5" mocap="true" pos="0 0 0">
      <geom name="m5" class="/" type="sphere" size="0.01" rgba="0 1 0 1" mass="0.0"/>
    </body>
    <body name="m6" mocap="true" pos="0 0 0">
      <geom name="m6" class="/" type="sphere" size="0.01" rgba="0 1 0 1" mass="0.0"/>
    </body>
    <body name="m7" mocap="true" pos="0 0 0">
      <geom name="m7" class="/" type="sphere" size="0.01" rgba="0 1 0 1" mass="0.0"/>
    </body>
    <body name="m8" mocap="true" pos="0 0 0">
      <geom name="m8" class="/" type="sphere" size="0.01" rgba="0 1 0 1" mass="0.0"/>
    </body>
    <body name="m9" mocap="true" pos="0 0 0">
      <geom name="m9" class="/" type="sphere" size="0.01" rgba="0 1 0 1" mass="0.0"/>
    </body>
    <body name="m10" mocap="true" pos="0 0 0">
      <geom name="m10" class="/" type="sphere" size="0.01" rgba="0 1 0 1" mass="0.0"/>
    </body>
    <body name="m11" mocap="true" pos="0 0 0">
      <geom name="m11" class="/" type="sphere" size="0.01" rgba="0 1 0 1" mass="0.0"/>
    </body>
    <body name="m12" mocap="true" pos="0 0 0">
      <geom name="m12" class="/" type="sphere" size="0.01" rgba="0 1 0 1" mass="0.0"/>
    </body>
    <body name="m13" mocap="true" pos="0 0 0">
      <geom name="m13" class="/" type="sphere" size="0.01" rgba="0 1 0 1" mass="0.0"/>
    </body>
    <body name="m14" mocap="true" pos="0 0 0">
      <geom name="m14" class="/" type="sphere" size="0.01" rgba="0 1 0 1" mass="0.0"/>
    </body>
    <body name="m15" mocap="true" pos="0 0 0">
      <geom name="m15" class="/" type="sphere" size="0.01" rgba="0 1 0 1" mass="0.0"/>
    </body>
    <body name="m16" mocap="true" pos="0 0 0">
      <geom name="m16" class="/" type="sphere" size="0.01" rgba="0 1 0 1" mass="0.0"/>
    </body>
    <body name="m17" mocap="true" pos="0 0 0">
      <geom name="m17" class="/" type="sphere" size="0.01" rgba="0 1 0 1" mass="0.0"/>
    </body>
    <body name="m18" mocap="true" pos="0 0 0">
      <geom name="m18" class="/" type="sphere" size="0.01" rgba="0 1 0 1" mass="0.0"/>
    </body>
    <body name="m19" mocap="true" pos="0 0 0">
      <geom name="m19" class="/" type="sphere" size="0.01" rgba="0 1 0 1" mass="0.0"/>
    </body>
    <body name="m20" mocap="true" pos="0 0 0">
      <geom name="m20" class="/" type="sphere" size="0.01" rgba="0 1 0 1" mass="0.0"/>
    </body>
    <body name="m21" mocap="true" pos="0 0 0">
      <geom name="m21" class="/" type="sphere" size="0.01" rgba="0 1 0 1" mass="0.0"/>
    </body>
    <body name="m22" mocap="true" pos="0 0 0">
      <geom name="m22" class="/" type="sphere" size="0.01" rgba="0 1 0 1" mass="0.0"/>
    </body>
    <body name="m23" mocap="true" pos="0 0 0">
      <geom name="m23" class="/" type="sphere" size="0.01" rgba="0 1 0 1" mass="0.0"/>
    </body>
    <body name="m24" mocap="true" pos="0 0 0">
      <geom name="m24" class="/" type="sphere" size="0.01" rgba="0 1 0 1" mass="0.0"/>
    </body>
    <body name="m25" mocap="true" pos="0 0 0">
      <geom name="m25" class="/" type="sphere" size="0.01" rgba="0 1 0 1" mass="0.0"/>
    </body>
    <body name="m26" mocap="true" pos="0 0 0">
      <geom name="m26" class="/" type="sphere" size="0.01" rgba="0 1 0 1" mass="0.0"/>
    </body>
    <body name="m27" mocap="true" pos="0 0 0">
      <geom name="m27" class="/" type="sphere" size="0.01" rgba="0 1 0 1" mass="0.0"/>
    </body>
    <body name="m28" mocap="true" pos="0 0 0">
      <geom name="m28" class="/" type="sphere" size="0.01" rgba="0 1 0 1" mass="0.0"/>
    </body>
    <body name="m29" mocap="true" pos="0 0 0">
      <geom name="m29" class="/" type="sphere" size="0.01" rgba="0 1 0 1" mass="0.0"/>
    </body>
    <body name="m30" mocap="true" pos="0 0 0">
      <geom name="m30" class="/" type="sphere" size="0.01" rgba="0 1 0 1" mass="0.0"/>
    </body>
    <body name="m31" mocap="true" pos="0 0 0">
      <geom name="m31" class="/" type="sphere" size="0.01" rgba="0 1 0 1" mass="0.0"/>
    </body>
    <body name="m32" mocap="true" pos="0 0 0">
      <geom name="m32" class="/" type="sphere" size="0.01" rgba="0 1 0 1" mass="0.0"/>
    </body>
    <body name="m33" mocap="true" pos="0 0 0">
      <geom name="m33" class="/" type="sphere" size="0.01" rgba="0 1 0 1" mass="0.0"/>
    </body>
    <body name="m34" mocap="true" pos="0 0 0">
      <geom name="m34" class="/" type="sphere" size="0.01" rgba="0 1 0 1" mass="0.0"/>
    </body>
    <body name="m35" mocap="true" pos="0 0 0">
      <geom name="m35" class="/" type="sphere" size="0.01" rgba="0 1 0 1" mass="0.0"/>
    </body>
    <body name="m36" mocap="true" pos="0 0 0">
      <geom name="m36" class="/" type="sphere" size="0.01" rgba="0 1 0 1" mass="0.0"/>
    </body>
    <body name="m37" mocap="true" pos="0 0 0">
      <geom name="m37" class="/" type="sphere" size="0.01" rgba="0 1 0 1" mass="0.0"/>
    </body>
    <body name="m38" mocap="true" pos="0 0 0">
      <geom name="m38" class="/" type="sphere" size="0.01" rgba="0 1 0 1" mass="0.0"/>
    </body>
    <body name="m39" mocap="true" pos="0 0 0">
      <geom name="m39" class="/" type="sphere" size="0.01" rgba="0 1 0 1" mass="0.0"/>
    </body>
  </worldbody>
  <equality>
    <weld name="world_root" class="/" active="false" body1="torso" relpose="0 0 -2 1 0 0 0"/>
  </equality>
  <actuator>
    <motor name="left_leg/hip_x" class="left_leg/" joint="left_leg/hip_x"/>
    <motor name="left_leg/hip_y" class="left_leg/" joint="left_leg/hip_y"/>
    <motor name="left_leg/knee" class="left_leg/" joint="left_leg/knee"/>
    <motor name="right_leg/hip_x" class="right_leg/" joint="right_leg/hip_x"/>
    <motor name="right_leg/hip_y" class="right_leg/" joint="right_leg/hip_y"/>
    <motor name="right_leg/knee" class="right_leg/" joint="right_leg/knee"/>
  </actuator>
</mujoco>
