<mujoco model="humanoid">
  <default>
    <default class="/"/>
    <default class="left_leg/"/>
    <default class="right_leg/"/>
  </default>
  <asset>
    <texture name="texplane" type="2d" builtin="checker" rgb1="0.20000000000000001 0.20000000000000001 0.20000000000000001" rgb2="0.29999999999999999 0.29999999999999999 0.29999999999999999" width="512" height="512"/>
    <material name="grid" class="/" texture="texplane" texrepeat="1 1" texuniform="true" reflectance="0.0"/>
  </asset>
  <worldbody>
    <geom name="floor" class="/" type="plane" conaffinity="1" size="100 100 0.20000000000000001" material="grid" pos="0 0 0"/>
    <body name="torso" pos="0.0000 0.0000 1.7925">
      <light name="top" class="/" mode="trackcom" pos="0 0 2"/>
      <camera name="back" class="/" mode="trackcom" pos="-3 0 1" xyaxes="0 -1 0 1 0 2"/>
      <camera name="side" class="/" mode="trackcom" pos="0 -3 1" xyaxes="1 0 0 0 1 2"/>
      <freejoint name="root"/>
      <geom name="torso" class="/" type="capsule" size="0.0700" fromto="0.0000 -0.1103 0.0000 0.0000 0.1103 0.0000"/>
      <site name="C7" class="/" type="sphere" rgba="1 0 0 1" size="0.0100" pos="-0.0450 0.0000 0.0779"/>
      <site name="RSHO" class="/" type="sphere" rgba="1 0 0 1" size="0.0100" pos="0.0000 -0.1654 0.0700"/>
      <site name="LSHO" class="/" type="sphere" rgba="1 0 0 1" size="0.0100" pos="0.0000 0.1654 0.0700"/>
      <site name="CLAV" class="/" type="sphere" rgba="1 0 0 1" size="0.0100" pos="0.0658 0.0000 0.0239"/>
      <geom name="upper_waist" class="/" type="capsule" size="0.0600" fromto="-0.0100 -0.0945 -0.1200 -0.0100 0.0945 -0.1200"/>
      <body name="head" pos="0.0000 0.0000 0.1900">
        <geom name="head" class="/" type="sphere" size="0.0900" pos="0.0000 0.0000 0.0000"/>
      </body>
      <camera name="egocentric" class="/" fovy="80.0" pos="0.089999999999999997 0 0" xyaxes="0 -1 0 0.10000000000000001 1 2"/>
      <body name="lower_waist" pos="-0.0100 0.0000 -0.2600" quat="1 0 -0.002 0">
        <geom name="lower_waist" class="/" type="capsule" size="0.0600" fromto="0.0000 -0.0945 0.0000 0.0000 0.0945 0.0000"/>
        <joint name="abdomen_z" class="/" type="hinge" pos="0 0 0.065000000000000002" axis="0 0 1" limited="true" solimplimit="0 0.98999999999999999 0.01" stiffness="20.0" range="-45 45" armature="0.01" damping="5.0"/>
        <joint name="abdomen_y" class="/" type="hinge" pos="0 0 0.065000000000000002" axis="0 1 0" limited="true" solimplimit="0 0.98999999999999999 0.01" stiffness="10.0" range="-75 30" armature="0.01" damping="5.0"/>
        <body name="pelvis" pos="0.0000 0.0000 -0.1650" quat="1 0 -0.002 0">
          <joint name="abdomen_x" class="/" type="hinge" pos="0 0 0.10000000000000001" axis="1 0 0" limited="true" solimplimit="0 0.98999999999999999 0.01" stiffness="10.0" range="-35 35" armature="0.01" damping="5.0"/>
          <geom name="butt" class="/" type="capsule" size="0.0900" fromto="-0.0200 -0.0903 0.0000 -0.0200 0.0903 0.0000"/>
          <site name="RASI" class="/" type="sphere" rgba="1 0 0 1" size="0.0100" pos="0.1013 -0.1148 0.0105"/>
          <site name="LASI" class="/" type="sphere" rgba="1 0 0 1" size="0.0100" pos="0.0624 0.1479 -0.0041"/>
          <site name="RPSI" class="/" type="sphere" rgba="1 0 0 1" size="0.0100" pos="-0.0903 -0.0385 0.0465"/>
          <site name="LPSI" class="/" type="sphere" rgba="1 0 0 1" size="0.0100" pos="-0.1037 0.0288 0.0444"/>
          <site name="left_leg_site" class="/" size="9.9999999999999995e-07 9.9999999999999995e-07 9.9999999999999995e-07" pos="0 0.1202500737954795 -0.040000000000000001"/>
          <body pos="0.0000 0.1203 -0.0400" name="left_leg/">
            <body name="left_leg/thigh" pos="0.0000 0.0000 0.0000">
              <joint name="left_leg/hip_x" class="left_leg/" type="hinge" axis="1 0 0" limited="true" solimplimit="0 0.98999999999999999 0.01" stiffness="10.0" range="-25 5" armature="0.01" damping="5.0"/>
              <joint name="left_leg/hip_z" class="left_leg/" type="hinge" axis="0 0 1" limited="true" solimplimit="0 0.98999999999999999 0.01" stiffness="10.0" range="-60 35" armature="0.01" damping="5.0"/>
              <joint name="left_leg/hip_y" class="left_leg/" type="hinge" axis="0 1 0" limited="true" solimplimit="0 0.98999999999999999 0.01" stiffness="20.0" range="-110 20" armature="0.01" damping="5.0"/>
              <geom name="left_leg/thigh" class="left_leg/" type="capsule" size="0.0603" fromto="0.0000 0.0000 0.0000 0.0000 -0.0100 -0.3943"/>
              <site name="left_leg/LGT" class="left_leg/" type="sphere" rgba="1 0 0 1" size="0.0100" pos="-0.0103 0.0669 -0.0107"/>
              <site name="left_leg/LT1" class="left_leg/" type="sphere" rgba="1 0 0 1" size="0.0100" pos="0.0603 0.0000 -0.1380"/>
              <site name="left_leg/LT2" class="left_leg/" type="sphere" rgba="1 0 0 1" size="0.0100" pos="0.0522 0.0301 -0.1971"/>
              <site name="left_leg/LT3" class="left_leg/" type="sphere" rgba="1 0 0 1" size="0.0100" pos="0.0603 0.0000 -0.2563"/>
              <site name="left_leg/LT4" class="left_leg/" type="sphere" rgba="1 0 0 1" size="0.0100" pos="0.0522 -0.0301 -0.1971"/>
              <body name="left_leg/shin" pos="0.0000 -0.0100 -0.4785">
                <joint name="left_leg/knee" class="left_leg/" type="hinge" pos="0 0 0.02" axis="0 -1 0" limited="true" solimplimit="0 0.98999999999999999 0.01" stiffness="1.0" range="-160 2" armature="0.01" damping="0.2"/>
                <geom name="left_leg/shin" class="left_leg/" type="capsule" size="0.0370" fromto="0.0000 0.0000 0.0000 0.0000 0.0000 -0.2925"/>
                <site name="left_leg/LKNL" class="left_leg/" type="sphere" rgba="1 0 0 1" size="0.0100" pos="-0.0055 0.0608 0.0268"/>
                <site name="left_leg/LKNM" class="left_leg/" type="sphere" rgba="1 0 0 1" size="0.0100" pos="-0.0056 -0.0596 0.0203"/>
                <site name="left_leg/LS1" class="left_leg/" type="sphere" rgba="1 0 0 1" size="0.0100" pos="0.0370 0.0000 -0.1024"/>
                <site name="left_leg/LS2" class="left_leg/" type="sphere" rgba="1 0 0 1" size="0.0100" pos="0.0321 0.0185 -0.1463"/>
                <site name="left_leg/LS3" class="left_leg/" type="sphere" rgba="1 0 0 1" size="0.0100" pos="0.0370 0.0000 -0.1902"/>
                <site name="left_leg/LS4" class="left_leg/" type="sphere" rgba="1 0 0 1" size="0.0100" pos="0.0321 -0.0185 -0.1463"/>
                <body name="left_leg/foot" pos="0.0000 0.0000 -0.3820">
                  <joint name="left_leg/ankle_y" class="left_leg/" type="hinge" pos="0 0 0.080000000000000002" axis="0 1 0" limited="true" solimplimit="0 0.98999999999999999 0.01" stiffness="6.0" range="-50 50" armature="0.01" damping="0.2"/>
                  <joint name="left_leg/ankle_x" class="left_leg/" type="hinge" pos="0 0 0.040000000000000001" axis="1 0 0.5" limited="true" solimplimit="0 0.98999999999999999 0.01" stiffness="3.0" range="-50 50" armature="0.01" damping="0.2"/>
                  <geom name="left_leg/right_foot" class="left_leg/" type="capsule" size="0.0264" fromto="-0.0677 0.0200 0.0000 0.1377 0.0200 0.0000"/>
                  <geom name="left_leg/left_foot" class="left_leg/" type="capsule" size="0.0264" fromto="-0.0677 -0.0200 0.0000 0.1377 -0.0200 0.0000"/>
                  <site name="left_leg/LANL" class="left_leg/" type="sphere" rgba="1 0 0 1" size="0.0100" pos="-0.0641 0.0481 0.0512"/>
                  <site name="left_leg/LANM" class="left_leg/" type="sphere" rgba="1 0 0 1" size="0.0100" pos="-0.0346 -0.0196 0.0463"/>
                  <site name="left_leg/LHEE" class="left_leg/" type="sphere" rgba="1 0 0 1" size="0.0100" pos="-0.0771 0.0000 0.0264"/>
                  <site name="left_leg/LM1" class="left_leg/" type="sphere" rgba="1 0 0 1" size="0.0100" pos="0.1336 -0.0208 0.0208"/>
                  <site name="left_leg/LM5" class="left_leg/" type="sphere" rgba="1 0 0 1" size="0.0100" pos="0.1336 0.0208 0.0208"/>
                  <body name="left_leg/ffp_0_0" pos="-0.0700 -0.0464 -0.0264"/>
                  <body name="left_leg/ffp_0_1" pos="-0.0700 -0.0253 -0.0264"/>
                  <body name="left_leg/ffp_0_2" pos="-0.0700 -0.0041 -0.0264"/>
                  <body name="left_leg/ffp_0_3" pos="-0.0700 0.0170 -0.0264"/>
                  <body name="left_leg/ffp_0_4" pos="-0.0700 0.0381 -0.0264"/>
                  <body name="left_leg/ffp_1_0" pos="-0.0472 -0.0464 -0.0264"/>
                  <body name="left_leg/ffp_1_1" pos="-0.0472 -0.0253 -0.0264"/>
                  <body name="left_leg/ffp_1_2" pos="-0.0472 -0.0041 -0.0264"/>
                  <body name="left_leg/ffp_1_3" pos="-0.0472 0.0170 -0.0264"/>
                  <body name="left_leg/ffp_1_4" pos="-0.0472 0.0381 -0.0264"/>
                  <body name="left_leg/ffp_2_0" pos="-0.0243 -0.0464 -0.0264"/>
                  <body name="left_leg/ffp_2_1" pos="-0.0243 -0.0253 -0.0264"/>
                  <body name="left_leg/ffp_2_2" pos="-0.0243 -0.0041 -0.0264"/>
                  <body name="left_leg/ffp_2_3" pos="-0.0243 0.0170 -0.0264"/>
                  <body name="left_leg/ffp_2_4" pos="-0.0243 0.0381 -0.0264"/>
                  <body name="left_leg/ffp_3_0" pos="-0.0015 -0.0464 -0.0264"/>
                  <body name="left_leg/ffp_3_1" pos="-0.0015 -0.0253 -0.0264"/>
                  <body name="left_leg/ffp_3_2" pos="-0.0015 -0.0041 -0.0264"/>
                  <body name="left_leg/ffp_3_3" pos="-0.0015 0.0170 -0.0264"/>
                  <body name="left_leg/ffp_3_4" pos="-0.0015 0.0381 -0.0264"/>
                  <body name="left_leg/ffp_4_0" pos="0.0213 -0.0464 -0.0264"/>
                  <body name="left_leg/ffp_4_1" pos="0.0213 -0.0253 -0.0264"/>
                  <body name="left_leg/ffp_4_2" pos="0.0213 -0.0041 -0.0264"/>
                  <body name="left_leg/ffp_4_3" pos="0.0213 0.0170 -0.0264"/>
                  <body name="left_leg/ffp_4_4" pos="0.0213 0.0381 -0.0264"/>
                  <body name="left_leg/ffp_5_0" pos="0.0442 -0.0464 -0.0264"/>
                  <body name="left_leg/ffp_5_1" pos="0.0442 -0.0253 -0.0264"/>
                  <body name="left_leg/ffp_5_2" pos="0.0442 -0.0041 -0.0264"/>
                  <body name="left_leg/ffp_5_3" pos="0.0442 0.0170 -0.0264"/>
                  <body name="left_leg/ffp_5_4" pos="0.0442 0.0381 -0.0264"/>
                  <body name="left_leg/ffp_6_0" pos="0.0670 -0.0464 -0.0264"/>
                  <body name="left_leg/ffp_6_1" pos="0.0670 -0.0253 -0.0264"/>
                  <body name="left_leg/ffp_6_2" pos="0.0670 -0.0041 -0.0264"/>
                  <body name="left_leg/ffp_6_3" pos="0.0670 0.0170 -0.0264"/>
                  <body name="left_leg/ffp_6_4" pos="0.0670 0.0381 -0.0264"/>
                  <body name="left_leg/ffp_7_0" pos="0.0898 -0.0464 -0.0264"/>
                  <body name="left_leg/ffp_7_1" pos="0.0898 -0.0253 -0.0264"/>
                  <body name="left_leg/ffp_7_2" pos="0.0898 -0.0041 -0.0264"/>
                  <body name="left_leg/ffp_7_3" pos="0.0898 0.0170 -0.0264"/>
                  <body name="left_leg/ffp_7_4" pos="0.0898 0.0381 -0.0264"/>
                  <body name="left_leg/ffp_8_0" pos="0.1126 -0.0464 -0.0264"/>
                  <body name="left_leg/ffp_8_1" pos="0.1126 -0.0253 -0.0264"/>
                  <body name="left_leg/ffp_8_2" pos="0.1126 -0.0041 -0.0264"/>
                  <body name="left_leg/ffp_8_3" pos="0.1126 0.0170 -0.0264"/>
                  <body name="left_leg/ffp_8_4" pos="0.1126 0.0381 -0.0264"/>
                </body>
              </body>
            </body>
          </body>
          <site name="right_leg_site" class="/" size="9.9999999999999995e-07 9.9999999999999995e-07 9.9999999999999995e-07" pos="0 -0.1202500737954795 -0.040000000000000001"/>
          <body pos="0.0000 -0.1203 -0.0400" name="right_leg/">
            <body name="right_leg/thigh" pos="0.0000 0.0000 0.0000">
              <joint name="right_leg/hip_x" class="right_leg/" type="hinge" axis="1 0 0" limited="true" solimplimit="0 0.98999999999999999 0.01" stiffness="10.0" range="-25 5" armature="0.01" damping="5.0"/>
              <joint name="right_leg/hip_z" class="right_leg/" type="hinge" axis="0 0 1" limited="true" solimplimit="0 0.98999999999999999 0.01" stiffness="10.0" range="-60 35" armature="0.01" damping="5.0"/>
              <joint name="right_leg/hip_y" class="right_leg/" type="hinge" axis="0 1 0" limited="true" solimplimit="0 0.98999999999999999 0.01" stiffness="20.0" range="-110 20" armature="0.01" damping="5.0"/>
              <geom name="right_leg/thigh" class="right_leg/" type="capsule" size="0.0603" fromto="0.0000 0.0000 0.0000 0.0000 0.0100 -0.3943"/>
              <site name="right_leg/RGT" class="right_leg/" type="sphere" rgba="1 0 0 1" size="0.0100" pos="0.0387 -0.0462 0.0000"/>
              <site name="right_leg/RT1" class="right_leg/" type="sphere" rgba="1 0 0 1" size="0.0100" pos="0.0603 0.0000 -0.1380"/>
              <site name="right_leg/RT2" class="right_leg/" type="sphere" rgba="1 0 0 1" size="0.0100" pos="0.0522 0.0301 -0.1971"/>
              <site name="right_leg/RT3" class="right_leg/" type="sphere" rgba="1 0 0 1" size="0.0100" pos="0.0603 0.0000 -0.2563"/>
              <site name="right_leg/RT4" class="right_leg/" type="sphere" rgba="1 0 0 1" size="0.0100" pos="0.0522 -0.0301 -0.1971"/>
              <body name="right_leg/shin" pos="0.0000 0.0100 -0.4785">
                <joint name="right_leg/knee" class="right_leg/" type="hinge" pos="0 0 0.02" axis="0 -1 0" limited="true" solimplimit="0 0.98999999999999999 0.01" stiffness="1.0" range="-160 2" armature="0.01" damping="0.2"/>
                <geom name="right_leg/shin" class="right_leg/" type="capsule" size="0.0370" fromto="0.0000 0.0000 0.0000 0.0000 0.0000 -0.2925"/>
                <site name="right_leg/RKNL" class="right_leg/" type="sphere" rgba="1 0 0 1" size="0.0100" pos="0.0039 -0.0601 0.0404"/>
                <site name="right_leg/RKNM" class="right_leg/" type="sphere" rgba="1 0 0 1" size="0.0100" pos="-0.0023 0.0715 0.0219"/>
                <site name="right_leg/RS1" class="right_leg/" type="sphere" rgba="1 0 0 1" size="0.0100" pos="0.0370 0.0000 -0.1024"/>
                <site name="right_leg/RS2" class="right_leg/" type="sphere" rgba="1 0 0 1" size="0.0100" pos="0.0321 0.0185 -0.1463"/>
                <site name="right_leg/RS3" class="right_leg/" type="sphere" rgba="1 0 0 1" size="0.0100" pos="0.0370 0.0000 -0.1902"/>
                <site name="right_leg/RS4" class="right_leg/" type="sphere" rgba="1 0 0 1" size="0.0100" pos="0.0321 -0.0185 -0.1463"/>
                <body name="right_leg/foot" pos="0.0000 0.0000 -0.3820">
                  <joint name="right_leg/ankle_y" class="right_leg/" type="hinge" pos="0 0 0.080000000000000002" axis="0 1 0" limited="true" solimplimit="0 0.98999999999999999 0.01" stiffness="6.0" range="-50 50" armature="0.01" damping="0.2"/>
                  <joint name="right_leg/ankle_x" class="right_leg/" type="hinge" pos="0 0 0.040000000000000001" axis="1 0 0.5" limited="true" solimplimit="0 0.98999999999999999 0.01" stiffness="3.0" range="-50 50" armature="0.01" damping="0.2"/>
                  <geom name="right_leg/right_foot" class="right_leg/" type="capsule" size="0.0264" fromto="-0.0677 -0.0200 0.0000 0.1377 -0.0200 0.0000"/>
                  <geom name="right_leg/left_foot" class="right_leg/" type="capsule" size="0.0264" fromto="-0.0677 0.0200 0.0000 0.1377 0.0200 0.0000"/>
                  <site name="right_leg/RANL" class="right_leg/" type="sphere" rgba="1 0 0 1" size="0.0100" pos="-0.0688 -0.0487 0.0570"/>
                  <site name="right_leg/RANM" class="right_leg/" type="sphere" rgba="1 0 0 1" size="0.0100" pos="-0.0553 0.0222 0.0498"/>
                  <site name="right_leg/RHEE" class="right_leg/" type="sphere" rgba="1 0 0 1" size="0.0100" pos="-0.0771 0.0000 0.0264"/>
                  <site name="right_leg/RM1" class="right_leg/" type="sphere" rgba="1 0 0 1" size="0.0100" pos="0.1336 0.0208 0.0208"/>
                  <site name="right_leg/RM5" class="right_leg/" type="sphere" rgba="1 0 0 1" size="0.0100" pos="0.1336 -0.0208 0.0208"/>
                  <body name="right_leg/ffp_0_0" pos="-0.0700 -0.0464 -0.0264"/>
                  <body name="right_leg/ffp_0_1" pos="-0.0700 -0.0253 -0.0264"/>
                  <body name="right_leg/ffp_0_2" pos="-0.0700 -0.0041 -0.0264"/>
                  <body name="right_leg/ffp_0_3" pos="-0.0700 0.0170 -0.0264"/>
                  <body name="right_leg/ffp_0_4" pos="-0.0700 0.0381 -0.0264"/>
                  <body name="right_leg/ffp_1_0" pos="-0.0472 -0.0464 -0.0264"/>
                  <body name="right_leg/ffp_1_1" pos="-0.0472 -0.0253 -0.0264"/>
                  <body name="right_leg/ffp_1_2" pos="-0.0472 -0.0041 -0.0264"/>
                  <body name="right_leg/ffp_1_3" pos="-0.0472 0.0170 -0.0264"/>
                  <body name="right_leg/ffp_1_4" pos="-0.0472 0.0381 -0.0264"/>
                  <body name="right_leg/ffp_2_0" pos="-0.0243 -0.0464 -0.0264"/>
                  <body name="right_leg/ffp_2_1" pos="-0.0243 -0.0253 -0.0264"/>
                  <body name="right_leg/ffp_2_2" pos="-0.0243 -0.0041 -0.0264"/>
                  <body name="right_leg/ffp_2_3" pos="-0.0243 0.0170 -0.0264"/>
                  <body name="right_leg/ffp_2_4" pos="-0.0243 0.0381 -0.0264"/>
                  <body name="right_leg/ffp_3_0" pos="-0.0015 -0.0464 -0.0264"/>
                  <body name="right_leg/ffp_3_1" pos="-0.0015 -0.0253 -0.0264"/>
                  <body name="right_leg/ffp_3_2" pos="-0.0015 -0.0041 -0.0264"/>
                  <body name="right_leg/ffp_3_3" pos="-0.0015 0.0170 -0.0264"/>
                  <body name="right_leg/ffp_3_4" pos="-0.0015 0.0381 -0.0264"/>
                  <body name="right_leg/ffp_4_0" pos="0.0213 -0.0464 -0.0264"/>
                  <body name="right_leg/ffp_4_1" pos="0.0213 -0.0253 -0.0264"/>
                  <body name="right_leg/ffp_4_2" pos="0.0213 -0.0041 -0.0264"/>
                  <body name="right_leg/ffp_4_3" pos="0.0213 0.0170 -0.0264"/>
                  <body name="right_leg/ffp_4_4" pos="0.0213 0.0381 -0.0264"/>
                  <body name="right_leg/ffp_5_0" pos="0.0442 -0.0464 -0.0264"/>
                  <body name="right_leg/ffp_5_1" pos="0.0442 -0.0253 -0.0264"/>
                  <body name="right_leg/ffp_5_2" pos="0.0442 -0.0041 -0.0264"/>
                  <body name="right_leg/ffp_5_3" pos="0.0442 0.0170 -0.0264"/>
                  <body name="right_leg/ffp_5_4" pos="0.0442 0.0381 -0.0264"/>
                  <body name="right_leg/ffp_6_0" pos="0.0670 -0.0464 -0.0264"/>
                  <body name="right_leg/ffp_6_1" pos="0.0670 -0.0253 -0.0264"/>
                  <body name="right_leg/ffp_6_2" pos="0.0670 -0.0041 -0.0264"/>
                  <body name="right_leg/ffp_6_3" pos="0.0670 0.0170 -0.0264"/>
                  <body name="right_leg/ffp_6_4" pos="0.0670 0.0381 -0.0264"/>
                  <body name="right_leg/ffp_7_0" pos="0.0898 -0.0464 -0.0264"/>
                  <body name="right_leg/ffp_7_1" pos="0.0898 -0.0253 -0.0264"/>
                  <body name="right_leg/ffp_7_2" pos="0.0898 -0.0041 -0.0264"/>
                  <body name="right_leg/ffp_7_3" pos="0.0898 0.0170 -0.0264"/>
                  <body name="right_leg/ffp_7_4" pos="0.0898 0.0381 -0.0264"/>
                  <body name="right_leg/ffp_8_0" pos="0.1126 -0.0464 -0.0264"/>
                  <body name="right_leg/ffp_8_1" pos="0.1126 -0.0253 -0.0264"/>
                  <body name="right_leg/ffp_8_2" pos="0.1126 -0.0041 -0.0264"/>
                  <body name="right_leg/ffp_8_3" pos="0.1126 0.0170 -0.0264"/>
                  <body name="right_leg/ffp_8_4" pos="0.1126 0.0381 -0.0264"/>
                </body>
              </body>
            </body>
          </body>
        </body>
      </body>
    </body>
    <body name="m0" mocap="true" pos="0 0 0">
      <geom name="m0" class="/" type="sphere" size="0.01" rgba="0 1 0 1"/>
    </body>
    <body name="m1" mocap="true" pos="0 0 0">
      <geom name="m1" class="/" type="sphere" size="0.01" rgba="0 1 0 1"/>
    </body>
    <body name="m2" mocap="true" pos="0 0 0">
      <geom name="m2" class="/" type="sphere" size="0.01" rgba="0 1 0 1"/>
    </body>
    <body name="m3" mocap="true" pos="0 0 0">
      <geom name="m3" class="/" type="sphere" size="0.01" rgba="0 1 0 1"/>
    </body>
    <body name="m4" mocap="true" pos="0 0 0">
      <geom name="m4" class="/" type="sphere" size="0.01" rgba="0 1 0 1"/>
    </body>
    <body name="m5" mocap="true" pos="0 0 0">
      <geom name="m5" class="/" type="sphere" size="0.01" rgba="0 1 0 1"/>
    </body>
    <body name="m6" mocap="true" pos="0 0 0">
      <geom name="m6" class="/" type="sphere" size="0.01" rgba="0 1 0 1"/>
    </body>
    <body name="m7" mocap="true" pos="0 0 0">
      <geom name="m7" class="/" type="sphere" size="0.01" rgba="0 1 0 1"/>
    </body>
    <body name="m8" mocap="true" pos="0 0 0">
      <geom name="m8" class="/" type="sphere" size="0.01" rgba="0 1 0 1"/>
    </body>
    <body name="m9" mocap="true" pos="0 0 0">
      <geom name="m9" class="/" type="sphere" size="0.01" rgba="0 1 0 1"/>
    </body>
    <body name="m10" mocap="true" pos="0 0 0">
      <geom name="m10" class="/" type="sphere" size="0.01" rgba="0 1 0 1"/>
    </body>
    <body name="m11" mocap="true" pos="0 0 0">
      <geom name="m11" class="/" type="sphere" size="0.01" rgba="0 1 0 1"/>
    </body>
    <body name="m12" mocap="true" pos="0 0 0">
      <geom name="m12" class="/" type="sphere" size="0.01" rgba="0 1 0 1"/>
    </body>
    <body name="m13" mocap="true" pos="0 0 0">
      <geom name="m13" class="/" type="sphere" size="0.01" rgba="0 1 0 1"/>
    </body>
    <body name="m14" mocap="true" pos="0 0 0">
      <geom name="m14" class="/" type="sphere" size="0.01" rgba="0 1 0 1"/>
    </body>
    <body name="m15" mocap="true" pos="0 0 0">
      <geom name="m15" class="/" type="sphere" size="0.01" rgba="0 1 0 1"/>
    </body>
    <body name="m16" mocap="true" pos="0 0 0">
      <geom name="m16" class="/" type="sphere" size="0.01" rgba="0 1 0 1"/>
    </body>
    <body name="m17" mocap="true" pos="0 0 0">
      <geom name="m17" class="/" type="sphere" size="0.01" rgba="0 1 0 1"/>
    </body>
    <body name="m18" mocap="true" pos="0 0 0">
      <geom name="m18" class="/" type="sphere" size="0.01" rgba="0 1 0 1"/>
    </body>
    <body name="m19" mocap="true" pos="0 0 0">
      <geom name="m19" class="/" type="sphere" size="0.01" rgba="0 1 0 1"/>
    </body>
    <body name="m20" mocap="true" pos="0 0 0">
      <geom name="m20" class="/" type="sphere" size="0.01" rgba="0 1 0 1"/>
    </body>
    <body name="m21" mocap="true" pos="0 0 0">
      <geom name="m21" class="/" type="sphere" size="0.01" rgba="0 1 0 1"/>
    </body>
    <body name="m22" mocap="true" pos="0 0 0">
      <geom name="m22" class="/" type="sphere" size="0.01" rgba="0 1 0 1"/>
    </body>
    <body name="m23" mocap="true" pos="0 0 0">
      <geom name="m23" class="/" type="sphere" size="0.01" rgba="0 1 0 1"/>
    </body>
    <body name="m24" mocap="true" pos="0 0 0">
      <geom name="m24" class="/" type="sphere" size="0.01" rgba="0 1 0 1"/>
    </body>
    <body name="m25" mocap="true" pos="0 0 0">
      <geom name="m25" class="/" type="sphere" size="0.01" rgba="0 1 0 1"/>
    </body>
    <body name="m26" mocap="true" pos="0 0 0">
      <geom name="m26" class="/" type="sphere" size="0.01" rgba="0 1 0 1"/>
    </body>
    <body name="m27" mocap="true" pos="0 0 0">
      <geom name="m27" class="/" type="sphere" size="0.01" rgba="0 1 0 1"/>
    </body>
    <body name="m28" mocap="true" pos="0 0 0">
      <geom name="m28" class="/" type="sphere" size="0.01" rgba="0 1 0 1"/>
    </body>
    <body name="m29" mocap="true" pos="0 0 0">
      <geom name="m29" class="/" type="sphere" size="0.01" rgba="0 1 0 1"/>
    </body>
    <body name="m30" mocap="true" pos="0 0 0">
      <geom name="m30" class="/" type="sphere" size="0.01" rgba="0 1 0 1"/>
    </body>
    <body name="m31" mocap="true" pos="0 0 0">
      <geom name="m31" class="/" type="sphere" size="0.01" rgba="0 1 0 1"/>
    </body>
    <body name="m32" mocap="true" pos="0 0 0">
      <geom name="m32" class="/" type="sphere" size="0.01" rgba="0 1 0 1"/>
    </body>
    <body name="m33" mocap="true" pos="0 0 0">
      <geom name="m33" class="/" type="sphere" size="0.01" rgba="0 1 0 1"/>
    </body>
    <body name="m34" mocap="true" pos="0 0 0">
      <geom name="m34" class="/" type="sphere" size="0.01" rgba="0 1 0 1"/>
    </body>
    <body name="m35" mocap="true" pos="0 0 0">
      <geom name="m35" class="/" type="sphere" size="0.01" rgba="0 1 0 1"/>
    </body>
    <body name="m36" mocap="true" pos="0 0 0">
      <geom name="m36" class="/" type="sphere" size="0.01" rgba="0 1 0 1"/>
    </body>
    <body name="m37" mocap="true" pos="0 0 0">
      <geom name="m37" class="/" type="sphere" size="0.01" rgba="0 1 0 1"/>
    </body>
    <body name="m38" mocap="true" pos="0 0 0">
      <geom name="m38" class="/" type="sphere" size="0.01" rgba="0 1 0 1"/>
    </body>
    <body name="m39" mocap="true" pos="0 0 0">
      <geom name="m39" class="/" type="sphere" size="0.01" rgba="0 1 0 1"/>
    </body>
  </worldbody>
  <equality>
    <weld name="world_root" class="/" active="false" body1="torso" relpose="0 0 -2 1 0 0 0"/>
    <joint name="abdomen_y" class="/" active="true" joint1="abdomen_y"/>
    <joint name="abdomen_z" class="/" active="true" joint1="abdomen_z"/>
    <joint name="abdomen_x" class="/" active="true" joint1="abdomen_x"/>
  </equality>
  <actuator>
    <motor name="abdomen_z" class="/" gear="40" joint="abdomen_z"/>
    <motor name="abdomen_y" class="/" gear="40" joint="abdomen_y"/>
    <motor name="abdomen_x" class="/" gear="40" joint="abdomen_x"/>
    <motor name="left_leg/hip_x" class="left_leg/" gear="40" joint="left_leg/hip_x"/>
    <motor name="left_leg/hip_z" class="left_leg/" gear="40" joint="left_leg/hip_z"/>
    <motor name="left_leg/hip_y" class="left_leg/" gear="120" joint="left_leg/hip_y"/>
    <motor name="left_leg/knee" class="left_leg/" gear="80" joint="left_leg/knee"/>
    <motor name="left_leg/ankle_y" class="left_leg/" gear="20" joint="left_leg/ankle_y"/>
    <motor name="left_leg/ankle_x" class="left_leg/" gear="20" joint="left_leg/ankle_x"/>
    <motor name="right_leg/hip_x" class="right_leg/" gear="40" joint="right_leg/hip_x"/>
    <motor name="right_leg/hip_z" class="right_leg/" gear="40" joint="right_leg/hip_z"/>
    <motor name="right_leg/hip_y" class="right_leg/" gear="120" joint="right_leg/hip_y"/>
    <motor name="right_leg/knee" class="right_leg/" gear="80" joint="right_leg/knee"/>
    <motor name="right_leg/ankle_y" class="right_leg/" gear="20" joint="right_leg/ankle_y"/>
    <motor name="right_leg/ankle_x" class="right_leg/" gear="20" joint="right_leg/ankle_x"/>
  </actuator>
</mujoco>
