<mujoco model="humanoid">
  <default>
    <default class="/"/>
    <default class="left_leg/"/>
    <default class="right_leg/"/>
  </default>
  <worldbody>
    <body name="floor" pos="0 0 0">
      <geom name="floor" class="/" type="plane" conaffinity="1" size="100 100 0.20000000000000001" pos="0 0 0"/>
    </body>
    <body name="torso" pos="0 0 1.5">
      <freejoint name="root"/>
      <geom name="torso" class="/" type="capsule" size="0.070000000000000007" fromto="0 -0.070000000000000007 0 0 0.070000000000000007 0"/>
      <geom name="upper_waist" class="/" type="capsule" size="0.059999999999999998" fromto="-0.01 -0.059999999999999998 -0.12 -0.01 0.059999999999999998 -0.12"/>
      <body name="head" pos="0 0 0.19">
        <geom name="head" class="/" type="sphere" size="0.089999999999999997"/>
      </body>
      <body name="lower_waist" pos="-0.01 0 -0.26000000000000001" quat="1 0 -0.002 0">
        <geom name="lower_waist" class="/" type="capsule" size="0.059999999999999998" fromto="0 -0.059999999999999998 0 0 0.059999999999999998 0"/>
        <joint name="abdomen_z" class="/" type="hinge" pos="0 0 0.065000000000000002" axis="0 0 1" limited="true" solimplimit="0 0.98999999999999999 0.01" stiffness="20.0" range="-45 45" armature="0.01" damping="5.0"/>
        <joint name="abdomen_y" class="/" type="hinge" pos="0 0 0.065000000000000002" axis="0 1 0" limited="true" solimplimit="0 0.98999999999999999 0.01" stiffness="10.0" range="-75 30" armature="0.01" damping="5.0"/>
        <body name="pelvis" pos="0 0 -0.16500000000000001" quat="1 0 -0.002 0">
          <joint name="abdomen_x" class="/" type="hinge" pos="0 0 0.10000000000000001" axis="1 0 0" limited="true" solimplimit="0 0.98999999999999999 0.01" stiffness="10.0" range="-35 35" armature="0.01" damping="5.0"/>
          <geom name="butt" class="/" type="capsule" size="0.089999999999999997" fromto="-0.02 -0.070000000000000007 0 -0.02 0.070000000000000007 0"/>
          <site name="left_leg_site" class="/" size="9.9999999999999995e-07 9.9999999999999995e-07 9.9999999999999995e-07" pos="0 0.10000000000000001 -0.040000000000000001"/>
          <body pos="0 0.10000000000000001 -0.040000000000000001" name="left_leg/">
            <body name="left_leg/thigh">
              <joint name="left_leg/hip_x" class="left_leg/" type="hinge" axis="1 0 0" limited="true" solimplimit="0 0.98999999999999999 0.01" stiffness="10.0" range="-25 5" armature="0.01" damping="5.0"/>
              <joint name="left_leg/hip_z" class="left_leg/" type="hinge" axis="0 0 1" limited="true" solimplimit="0 0.98999999999999999 0.01" stiffness="10.0" range="-60 35" armature="0.01" damping="5.0"/>
              <joint name="left_leg/hip_y" class="left_leg/" type="hinge" axis="0 1 0" limited="true" solimplimit="0 0.98999999999999999 0.01" stiffness="20.0" range="-110 20" armature="0.01" damping="5.0"/>
              <geom name="left_leg/thigh" class="left_leg/" type="capsule" size="0.059999999999999998" fromto="0 0 0 0 0.02 -0.68000000000000005"/>
              <body name="left_leg/shin" pos="0 0.01 -0.40300000000000002">
                <joint name="left_leg/knee" class="left_leg/" type="hinge" pos="0 0 0.02" axis="0 -1 0" limited="true" solimplimit="0 0.98999999999999999 0.01" stiffness="1.0" range="-160 2" armature="0.01" damping="0.2"/>
                <geom name="left_leg/shin" class="left_leg/" type="capsule" size="0.049000000000000002" fromto="0 0 0 0 0 -0.29999999999999999"/>
                <body name="left_leg/foot" pos="0 0 -0.39000000000000001">
                  <joint name="left_leg/ankle_y" class="left_leg/" type="hinge" pos="0 0 0.080000000000000002" axis="0 1 0" limited="true" solimplimit="0 0.98999999999999999 0.01" stiffness="6.0" range="-50 50" armature="0.01" damping="0.2"/>
                  <joint name="left_leg/ankle_x" class="left_leg/" type="hinge" pos="0 0 0.040000000000000001" axis="1 0 0.5" limited="true" solimplimit="0 0.98999999999999999 0.01" stiffness="3.0" range="-50 50" armature="0.01" damping="0.2"/>
                  <geom name="left_leg/right_foot" class="left_leg/" type="capsule" size="0.027" fromto="-0.070000000000000007 -0.02 0 0.14000000000000001 -0.040000000000000001 0"/>
                  <geom name="left_leg/left_foot" class="left_leg/" type="capsule" size="0.027" fromto="-0.070000000000000007 0 0 0.14000000000000001 0.02 0"/>
                </body>
              </body>
            </body>
          </body>
          <site name="right_leg_site" class="/" size="9.9999999999999995e-07 9.9999999999999995e-07 9.9999999999999995e-07" pos="0 -0.10000000000000001 -0.040000000000000001"/>
          <body pos="0 -0.10000000000000001 -0.040000000000000001" name="right_leg/">
            <body name="right_leg/thigh">
              <joint name="right_leg/hip_x" class="right_leg/" type="hinge" axis="1 0 0" limited="true" solimplimit="0 0.98999999999999999 0.01" stiffness="10.0" range="-25 5" armature="0.01" damping="5.0"/>
              <joint name="right_leg/hip_z" class="right_leg/" type="hinge" axis="0 0 1" limited="true" solimplimit="0 0.98999999999999999 0.01" stiffness="10.0" range="-60 35" armature="0.01" damping="5.0"/>
              <joint name="right_leg/hip_y" class="right_leg/" type="hinge" axis="0 1 0" limited="true" solimplimit="0 0.98999999999999999 0.01" stiffness="20.0" range="-110 20" armature="0.01" damping="5.0"/>
              <geom name="right_leg/thigh" class="right_leg/" type="capsule" size="0.059999999999999998" fromto="0 0 0 0 0.01 -0.34000000000000002"/>
              <body name="right_leg/shin" pos="0 0.01 -0.40300000000000002">
                <joint name="right_leg/knee" class="right_leg/" type="hinge" pos="0 0 0.02" axis="0 -1 0" limited="true" solimplimit="0 0.98999999999999999 0.01" stiffness="1.0" range="-160 2" armature="0.01" damping="0.2"/>
                <geom name="right_leg/shin" class="right_leg/" type="capsule" size="0.049000000000000002" fromto="0 0 0 0 0 -0.29999999999999999"/>
                <body name="right_leg/foot" pos="0 0 -0.39000000000000001">
                  <joint name="right_leg/ankle_y" class="right_leg/" type="hinge" pos="0 0 0.080000000000000002" axis="0 1 0" limited="true" solimplimit="0 0.98999999999999999 0.01" stiffness="6.0" range="-50 50" armature="0.01" damping="0.2"/>
                  <joint name="right_leg/ankle_x" class="right_leg/" type="hinge" pos="0 0 0.040000000000000001" axis="1 0 0.5" limited="true" solimplimit="0 0.98999999999999999 0.01" stiffness="3.0" range="-50 50" armature="0.01" damping="0.2"/>
                  <geom name="right_leg/right_foot" class="right_leg/" type="capsule" size="0.027" fromto="-0.070000000000000007 -0.02 0 0.14000000000000001 -0.040000000000000001 0"/>
                  <geom name="right_leg/left_foot" class="right_leg/" type="capsule" size="0.027" fromto="-0.070000000000000007 0 0 0.14000000000000001 0.02 0"/>
                </body>
              </body>
            </body>
          </body>
        </body>
      </body>
    </body>
  </worldbody>
</mujoco>
