<?xml version="0.0" ?>
<robot name="humanoid">
	<link name="torso">
		<inertial>
			<origin rpy="0.00000 -0.00000 0.00000" xyz="-0.01000 0.00000 -0.12000"/>
			<mass value="5.85383"/>
			<inertia ixx="0.06873" ixy="0" ixz="0" iyy="0.04005" iyz="0" izz="0.04781"/>
		</inertial>
		<collision>
			<origin rpy="-1.57080 0.00000 0.00000" xyz="0.00000 0.00000 0.00000"/>
			<geometry>
				<cylinder length="0.14000" radius="0.07000"/>
			</geometry>
		</collision>
		<collision>
			<origin rpy="-1.57080 0.00000 0.00000" xyz="-0.01000 0.00000 -0.12000"/>
			<geometry>
				<cylinder length="0.12000" radius="0.06000"/>
			</geometry>
		</collision>
	</link>
	<link name="head">
		<inertial>
			<origin rpy="0.00000 -0.00000 0.00000" xyz="0.00000 0.00000 0.00000"/>
			<mass value="3.05363"/>
			<inertia ixx="0.00989" ixy="0" ixz="0" iyy="0.00989" iyz="0" izz="0.00989"/>
		</inertial>
		<collision>
			<origin rpy="0.00000 -0.00000 0.00000" xyz="0.00000 0.00000 0.00000"/>
			<geometry>
				<sphere radius="0.09000"/>
			</geometry>
		</collision>
	</link>
	<link name="link1_3">
		<inertial>
			<origin rpy="0.00000 -0.00000 0.00000" xyz="0.00000 0.00000 0.00000"/>
			<mass value="0.00000"/>
			<inertia ixx="0.00000" ixy="0" ixz="0" iyy="0.00000" iyz="0" izz="0.00000"/>
		</inertial>
	</link>
	<link name="link1_4">
		<inertial>
			<origin rpy="0.00000 -0.00000 0.00000" xyz="0.00000 0.00000 0.00000"/>
			<mass value="0.00000"/>
			<inertia ixx="0.00000" ixy="0" ixz="0" iyy="0.00000" iyz="0" izz="0.00000"/>
		</inertial>
	</link>
	<link name="lower_waist">
		<inertial>
			<origin rpy="0.00000 -0.00000 0.00000" xyz="0.00000 0.00000 0.00000"/>
			<mass value="2.26195"/>
			<inertia ixx="0.01357" ixy="0" ixz="0" iyy="0.00543" iyz="0" izz="0.01357"/>
		</inertial>
		<collision>
			<origin rpy="-1.57080 0.00000 0.00000" xyz="0.00000 0.00000 0.00000"/>
			<geometry>
				<cylinder length="0.12000" radius="0.06000"/>
			</geometry>
		</collision>
	</link>
	<link name="link1_6">
		<inertial>
			<origin rpy="0.00000 -0.00000 0.00000" xyz="0.00000 0.00000 0.00000"/>
			<mass value="0.00000"/>
			<inertia ixx="0.00000" ixy="0" ixz="0" iyy="0.00000" iyz="0" izz="0.00000"/>
		</inertial>
	</link>
	<link name="pelvis">
		<inertial>
			<origin rpy="0.00000 -0.00000 0.00000" xyz="-0.02000 0.00000 0.00000"/>
			<mass value="6.61619"/>
			<inertia ixx="0.07432" ixy="0" ixz="0" iyy="0.03573" iyz="0" izz="0.07432"/>
		</inertial>
		<collision>
			<origin rpy="-1.57080 0.00000 0.00000" xyz="-0.02000 0.00000 0.00000"/>
			<geometry>
				<cylinder length="0.14000" radius="0.09000"/>
			</geometry>
		</collision>
	</link>
	<link name="left_leg/">
		<inertial>
			<origin rpy="0.00000 -0.00000 0.00000" xyz="0.00000 0.00000 0.00000"/>
			<mass value="0.00000"/>
			<inertia ixx="0.00000" ixy="0" ixz="0" iyy="0.00000" iyz="0" izz="0.00000"/>
		</inertial>
	</link>
	<link name="link1_9">
		<inertial>
			<origin rpy="0.00000 -0.00000 0.00000" xyz="0.00000 0.00000 0.00000"/>
			<mass value="0.00000"/>
			<inertia ixx="0.00000" ixy="0" ixz="0" iyy="0.00000" iyz="0" izz="0.00000"/>
		</inertial>
	</link>
	<link name="link1_10">
		<inertial>
			<origin rpy="0.00000 -0.00000 0.00000" xyz="0.00000 0.00000 0.00000"/>
			<mass value="0.00000"/>
			<inertia ixx="0.00000" ixy="0" ixz="0" iyy="0.00000" iyz="0" izz="0.00000"/>
		</inertial>
	</link>
	<link name="link1_11">
		<inertial>
			<origin rpy="0.00000 -0.00000 0.00000" xyz="0.00000 0.00000 0.00000"/>
			<mass value="0.00000"/>
			<inertia ixx="0.00000" ixy="0" ixz="0" iyy="0.00000" iyz="0" izz="0.00000"/>
		</inertial>
	</link>
	<link name="left_leg/thigh">
		<inertial>
			<origin rpy="0.00000 -0.00000 0.00000" xyz="0.00000 -0.00500 -0.14000"/>
			<mass value="4.07352"/>
			<inertia ixx="0.06158" ixy="0" ixz="0" iyy="0.06035" iyz="0" izz="0.01100"/>
		</inertial>
		<collision>
			<origin rpy="3.10589 -0.00000 0.00000" xyz="0.00000 -0.00500 -0.14000"/>
			<geometry>
				<cylinder length="0.28018" radius="0.06000"/>
			</geometry>
		</collision>
	</link>
	<link name="link1_13">
		<inertial>
			<origin rpy="0.00000 -0.00000 0.00000" xyz="0.00000 0.00000 0.00000"/>
			<mass value="0.00000"/>
			<inertia ixx="0.00000" ixy="0" ixz="0" iyy="0.00000" iyz="0" izz="0.00000"/>
		</inertial>
	</link>
	<link name="left_leg/shin">
		<inertial>
			<origin rpy="0.00000 -0.00000 0.00000" xyz="0.00000 0.00000 -0.10100"/>
			<mass value="2.01649"/>
			<inertia ixx="0.01674" ixy="0" ixz="0" iyy="0.01674" iyz="0" izz="0.00323"/>
		</inertial>
		<collision>
			<origin rpy="3.14159 -0.00000 3.14159" xyz="0.00000 0.00000 -0.10100"/>
			<geometry>
				<cylinder length="0.20200" radius="0.04900"/>
			</geometry>
		</collision>
	</link>
	<link name="link1_15">
		<inertial>
			<origin rpy="0.00000 -0.00000 0.00000" xyz="0.00000 0.00000 0.00000"/>
			<mass value="0.00000"/>
			<inertia ixx="0.00000" ixy="0" ixz="0" iyy="0.00000" iyz="0" izz="0.00000"/>
		</inertial>
	</link>
	<link name="link1_16">
		<inertial>
			<origin rpy="0.00000 -0.00000 0.00000" xyz="0.00000 0.00000 0.00000"/>
			<mass value="0.00000"/>
			<inertia ixx="0.00000" ixy="0" ixz="0" iyy="0.00000" iyz="0" izz="0.00000"/>
		</inertial>
	</link>
	<link name="left_leg/foot">
		<inertial>
			<origin rpy="0.00000 -0.00000 0.00000" xyz="0.03500 -0.02000 0.00000"/>
			<mass value="1.12679"/>
			<inertia ixx="0.00110" ixy="0" ixz="0" iyy="0.00682" iyz="0" izz="0.00737"/>
		</inertial>
		<collision>
			<origin rpy="0.00000 1.57080 -0.00000" xyz="0.03500 0.02000 0.00000"/>
			<geometry>
				<cylinder length="0.21000" radius="0.02700"/>
			</geometry>
		</collision>
		<collision>
			<origin rpy="0.00000 1.57080 -0.00000" xyz="0.03500 -0.02000 0.00000"/>
			<geometry>
				<cylinder length="0.21000" radius="0.02700"/>
			</geometry>
		</collision>
	</link>
	<link name="left_leg/ffp_0_0">
		<inertial>
			<origin rpy="0.00000 -0.00000 0.00000" xyz="0.00000 0.00000 0.00000"/>
			<mass value="0.00000"/>
			<inertia ixx="0.00000" ixy="0" ixz="0" iyy="0.00000" iyz="0" izz="0.00000"/>
		</inertial>
	</link>
	<link name="left_leg/ffp_0_1">
		<inertial>
			<origin rpy="0.00000 -0.00000 0.00000" xyz="0.00000 0.00000 0.00000"/>
			<mass value="0.00000"/>
			<inertia ixx="0.00000" ixy="0" ixz="0" iyy="0.00000" iyz="0" izz="0.00000"/>
		</inertial>
	</link>
	<link name="left_leg/ffp_0_2">
		<inertial>
			<origin rpy="0.00000 -0.00000 0.00000" xyz="0.00000 0.00000 0.00000"/>
			<mass value="0.00000"/>
			<inertia ixx="0.00000" ixy="0" ixz="0" iyy="0.00000" iyz="0" izz="0.00000"/>
		</inertial>
	</link>
	<link name="left_leg/ffp_0_3">
		<inertial>
			<origin rpy="0.00000 -0.00000 0.00000" xyz="0.00000 0.00000 0.00000"/>
			<mass value="0.00000"/>
			<inertia ixx="0.00000" ixy="0" ixz="0" iyy="0.00000" iyz="0" izz="0.00000"/>
		</inertial>
	</link>
	<link name="left_leg/ffp_0_4">
		<inertial>
			<origin rpy="0.00000 -0.00000 0.00000" xyz="0.00000 0.00000 0.00000"/>
			<mass value="0.00000"/>
			<inertia ixx="0.00000" ixy="0" ixz="0" iyy="0.00000" iyz="0" izz="0.00000"/>
		</inertial>
	</link>
	<link name="left_leg/ffp_1_0">
		<inertial>
			<origin rpy="0.00000 -0.00000 0.00000" xyz="0.00000 0.00000 0.00000"/>
			<mass value="0.00000"/>
			<inertia ixx="0.00000" ixy="0" ixz="0" iyy="0.00000" iyz="0" izz="0.00000"/>
		</inertial>
	</link>
	<link name="left_leg/ffp_1_1">
		<inertial>
			<origin rpy="0.00000 -0.00000 0.00000" xyz="0.00000 0.00000 0.00000"/>
			<mass value="0.00000"/>
			<inertia ixx="0.00000" ixy="0" ixz="0" iyy="0.00000" iyz="0" izz="0.00000"/>
		</inertial>
	</link>
	<link name="left_leg/ffp_1_2">
		<inertial>
			<origin rpy="0.00000 -0.00000 0.00000" xyz="0.00000 0.00000 0.00000"/>
			<mass value="0.00000"/>
			<inertia ixx="0.00000" ixy="0" ixz="0" iyy="0.00000" iyz="0" izz="0.00000"/>
		</inertial>
	</link>
	<link name="left_leg/ffp_1_3">
		<inertial>
			<origin rpy="0.00000 -0.00000 0.00000" xyz="0.00000 0.00000 0.00000"/>
			<mass value="0.00000"/>
			<inertia ixx="0.00000" ixy="0" ixz="0" iyy="0.00000" iyz="0" izz="0.00000"/>
		</inertial>
	</link>
	<link name="left_leg/ffp_1_4">
		<inertial>
			<origin rpy="0.00000 -0.00000 0.00000" xyz="0.00000 0.00000 0.00000"/>
			<mass value="0.00000"/>
			<inertia ixx="0.00000" ixy="0" ixz="0" iyy="0.00000" iyz="0" izz="0.00000"/>
		</inertial>
	</link>
	<link name="left_leg/ffp_2_0">
		<inertial>
			<origin rpy="0.00000 -0.00000 0.00000" xyz="0.00000 0.00000 0.00000"/>
			<mass value="0.00000"/>
			<inertia ixx="0.00000" ixy="0" ixz="0" iyy="0.00000" iyz="0" izz="0.00000"/>
		</inertial>
	</link>
	<link name="left_leg/ffp_2_1">
		<inertial>
			<origin rpy="0.00000 -0.00000 0.00000" xyz="0.00000 0.00000 0.00000"/>
			<mass value="0.00000"/>
			<inertia ixx="0.00000" ixy="0" ixz="0" iyy="0.00000" iyz="0" izz="0.00000"/>
		</inertial>
	</link>
	<link name="left_leg/ffp_2_2">
		<inertial>
			<origin rpy="0.00000 -0.00000 0.00000" xyz="0.00000 0.00000 0.00000"/>
			<mass value="0.00000"/>
			<inertia ixx="0.00000" ixy="0" ixz="0" iyy="0.00000" iyz="0" izz="0.00000"/>
		</inertial>
	</link>
	<link name="left_leg/ffp_2_3">
		<inertial>
			<origin rpy="0.00000 -0.00000 0.00000" xyz="0.00000 0.00000 0.00000"/>
			<mass value="0.00000"/>
			<inertia ixx="0.00000" ixy="0" ixz="0" iyy="0.00000" iyz="0" izz="0.00000"/>
		</inertial>
	</link>
	<link name="left_leg/ffp_2_4">
		<inertial>
			<origin rpy="0.00000 -0.00000 0.00000" xyz="0.00000 0.00000 0.00000"/>
			<mass value="0.00000"/>
			<inertia ixx="0.00000" ixy="0" ixz="0" iyy="0.00000" iyz="0" izz="0.00000"/>
		</inertial>
	</link>
	<link name="left_leg/ffp_3_0">
		<inertial>
			<origin rpy="0.00000 -0.00000 0.00000" xyz="0.00000 0.00000 0.00000"/>
			<mass value="0.00000"/>
			<inertia ixx="0.00000" ixy="0" ixz="0" iyy="0.00000" iyz="0" izz="0.00000"/>
		</inertial>
	</link>
	<link name="left_leg/ffp_3_1">
		<inertial>
			<origin rpy="0.00000 -0.00000 0.00000" xyz="0.00000 0.00000 0.00000"/>
			<mass value="0.00000"/>
			<inertia ixx="0.00000" ixy="0" ixz="0" iyy="0.00000" iyz="0" izz="0.00000"/>
		</inertial>
	</link>
	<link name="left_leg/ffp_3_2">
		<inertial>
			<origin rpy="0.00000 -0.00000 0.00000" xyz="0.00000 0.00000 0.00000"/>
			<mass value="0.00000"/>
			<inertia ixx="0.00000" ixy="0" ixz="0" iyy="0.00000" iyz="0" izz="0.00000"/>
		</inertial>
	</link>
	<link name="left_leg/ffp_3_3">
		<inertial>
			<origin rpy="0.00000 -0.00000 0.00000" xyz="0.00000 0.00000 0.00000"/>
			<mass value="0.00000"/>
			<inertia ixx="0.00000" ixy="0" ixz="0" iyy="0.00000" iyz="0" izz="0.00000"/>
		</inertial>
	</link>
	<link name="left_leg/ffp_3_4">
		<inertial>
			<origin rpy="0.00000 -0.00000 0.00000" xyz="0.00000 0.00000 0.00000"/>
			<mass value="0.00000"/>
			<inertia ixx="0.00000" ixy="0" ixz="0" iyy="0.00000" iyz="0" izz="0.00000"/>
		</inertial>
	</link>
	<link name="left_leg/ffp_4_0">
		<inertial>
			<origin rpy="0.00000 -0.00000 0.00000" xyz="0.00000 0.00000 0.00000"/>
			<mass value="0.00000"/>
			<inertia ixx="0.00000" ixy="0" ixz="0" iyy="0.00000" iyz="0" izz="0.00000"/>
		</inertial>
	</link>
	<link name="left_leg/ffp_4_1">
		<inertial>
			<origin rpy="0.00000 -0.00000 0.00000" xyz="0.00000 0.00000 0.00000"/>
			<mass value="0.00000"/>
			<inertia ixx="0.00000" ixy="0" ixz="0" iyy="0.00000" iyz="0" izz="0.00000"/>
		</inertial>
	</link>
	<link name="left_leg/ffp_4_2">
		<inertial>
			<origin rpy="0.00000 -0.00000 0.00000" xyz="0.00000 0.00000 0.00000"/>
			<mass value="0.00000"/>
			<inertia ixx="0.00000" ixy="0" ixz="0" iyy="0.00000" iyz="0" izz="0.00000"/>
		</inertial>
	</link>
	<link name="left_leg/ffp_4_3">
		<inertial>
			<origin rpy="0.00000 -0.00000 0.00000" xyz="0.00000 0.00000 0.00000"/>
			<mass value="0.00000"/>
			<inertia ixx="0.00000" ixy="0" ixz="0" iyy="0.00000" iyz="0" izz="0.00000"/>
		</inertial>
	</link>
	<link name="left_leg/ffp_4_4">
		<inertial>
			<origin rpy="0.00000 -0.00000 0.00000" xyz="0.00000 0.00000 0.00000"/>
			<mass value="0.00000"/>
			<inertia ixx="0.00000" ixy="0" ixz="0" iyy="0.00000" iyz="0" izz="0.00000"/>
		</inertial>
	</link>
	<link name="left_leg/ffp_5_0">
		<inertial>
			<origin rpy="0.00000 -0.00000 0.00000" xyz="0.00000 0.00000 0.00000"/>
			<mass value="0.00000"/>
			<inertia ixx="0.00000" ixy="0" ixz="0" iyy="0.00000" iyz="0" izz="0.00000"/>
		</inertial>
	</link>
	<link name="left_leg/ffp_5_1">
		<inertial>
			<origin rpy="0.00000 -0.00000 0.00000" xyz="0.00000 0.00000 0.00000"/>
			<mass value="0.00000"/>
			<inertia ixx="0.00000" ixy="0" ixz="0" iyy="0.00000" iyz="0" izz="0.00000"/>
		</inertial>
	</link>
	<link name="left_leg/ffp_5_2">
		<inertial>
			<origin rpy="0.00000 -0.00000 0.00000" xyz="0.00000 0.00000 0.00000"/>
			<mass value="0.00000"/>
			<inertia ixx="0.00000" ixy="0" ixz="0" iyy="0.00000" iyz="0" izz="0.00000"/>
		</inertial>
	</link>
	<link name="left_leg/ffp_5_3">
		<inertial>
			<origin rpy="0.00000 -0.00000 0.00000" xyz="0.00000 0.00000 0.00000"/>
			<mass value="0.00000"/>
			<inertia ixx="0.00000" ixy="0" ixz="0" iyy="0.00000" iyz="0" izz="0.00000"/>
		</inertial>
	</link>
	<link name="left_leg/ffp_5_4">
		<inertial>
			<origin rpy="0.00000 -0.00000 0.00000" xyz="0.00000 0.00000 0.00000"/>
			<mass value="0.00000"/>
			<inertia ixx="0.00000" ixy="0" ixz="0" iyy="0.00000" iyz="0" izz="0.00000"/>
		</inertial>
	</link>
	<link name="left_leg/ffp_6_0">
		<inertial>
			<origin rpy="0.00000 -0.00000 0.00000" xyz="0.00000 0.00000 0.00000"/>
			<mass value="0.00000"/>
			<inertia ixx="0.00000" ixy="0" ixz="0" iyy="0.00000" iyz="0" izz="0.00000"/>
		</inertial>
	</link>
	<link name="left_leg/ffp_6_1">
		<inertial>
			<origin rpy="0.00000 -0.00000 0.00000" xyz="0.00000 0.00000 0.00000"/>
			<mass value="0.00000"/>
			<inertia ixx="0.00000" ixy="0" ixz="0" iyy="0.00000" iyz="0" izz="0.00000"/>
		</inertial>
	</link>
	<link name="left_leg/ffp_6_2">
		<inertial>
			<origin rpy="0.00000 -0.00000 0.00000" xyz="0.00000 0.00000 0.00000"/>
			<mass value="0.00000"/>
			<inertia ixx="0.00000" ixy="0" ixz="0" iyy="0.00000" iyz="0" izz="0.00000"/>
		</inertial>
	</link>
	<link name="left_leg/ffp_6_3">
		<inertial>
			<origin rpy="0.00000 -0.00000 0.00000" xyz="0.00000 0.00000 0.00000"/>
			<mass value="0.00000"/>
			<inertia ixx="0.00000" ixy="0" ixz="0" iyy="0.00000" iyz="0" izz="0.00000"/>
		</inertial>
	</link>
	<link name="left_leg/ffp_6_4">
		<inertial>
			<origin rpy="0.00000 -0.00000 0.00000" xyz="0.00000 0.00000 0.00000"/>
			<mass value="0.00000"/>
			<inertia ixx="0.00000" ixy="0" ixz="0" iyy="0.00000" iyz="0" izz="0.00000"/>
		</inertial>
	</link>
	<link name="left_leg/ffp_7_0">
		<inertial>
			<origin rpy="0.00000 -0.00000 0.00000" xyz="0.00000 0.00000 0.00000"/>
			<mass value="0.00000"/>
			<inertia ixx="0.00000" ixy="0" ixz="0" iyy="0.00000" iyz="0" izz="0.00000"/>
		</inertial>
	</link>
	<link name="left_leg/ffp_7_1">
		<inertial>
			<origin rpy="0.00000 -0.00000 0.00000" xyz="0.00000 0.00000 0.00000"/>
			<mass value="0.00000"/>
			<inertia ixx="0.00000" ixy="0" ixz="0" iyy="0.00000" iyz="0" izz="0.00000"/>
		</inertial>
	</link>
	<link name="left_leg/ffp_7_2">
		<inertial>
			<origin rpy="0.00000 -0.00000 0.00000" xyz="0.00000 0.00000 0.00000"/>
			<mass value="0.00000"/>
			<inertia ixx="0.00000" ixy="0" ixz="0" iyy="0.00000" iyz="0" izz="0.00000"/>
		</inertial>
	</link>
	<link name="left_leg/ffp_7_3">
		<inertial>
			<origin rpy="0.00000 -0.00000 0.00000" xyz="0.00000 0.00000 0.00000"/>
			<mass value="0.00000"/>
			<inertia ixx="0.00000" ixy="0" ixz="0" iyy="0.00000" iyz="0" izz="0.00000"/>
		</inertial>
	</link>
	<link name="left_leg/ffp_7_4">
		<inertial>
			<origin rpy="0.00000 -0.00000 0.00000" xyz="0.00000 0.00000 0.00000"/>
			<mass value="0.00000"/>
			<inertia ixx="0.00000" ixy="0" ixz="0" iyy="0.00000" iyz="0" izz="0.00000"/>
		</inertial>
	</link>
	<link name="left_leg/ffp_8_0">
		<inertial>
			<origin rpy="0.00000 -0.00000 0.00000" xyz="0.00000 0.00000 0.00000"/>
			<mass value="0.00000"/>
			<inertia ixx="0.00000" ixy="0" ixz="0" iyy="0.00000" iyz="0" izz="0.00000"/>
		</inertial>
	</link>
	<link name="left_leg/ffp_8_1">
		<inertial>
			<origin rpy="0.00000 -0.00000 0.00000" xyz="0.00000 0.00000 0.00000"/>
			<mass value="0.00000"/>
			<inertia ixx="0.00000" ixy="0" ixz="0" iyy="0.00000" iyz="0" izz="0.00000"/>
		</inertial>
	</link>
	<link name="left_leg/ffp_8_2">
		<inertial>
			<origin rpy="0.00000 -0.00000 0.00000" xyz="0.00000 0.00000 0.00000"/>
			<mass value="0.00000"/>
			<inertia ixx="0.00000" ixy="0" ixz="0" iyy="0.00000" iyz="0" izz="0.00000"/>
		</inertial>
	</link>
	<link name="left_leg/ffp_8_3">
		<inertial>
			<origin rpy="0.00000 -0.00000 0.00000" xyz="0.00000 0.00000 0.00000"/>
			<mass value="0.00000"/>
			<inertia ixx="0.00000" ixy="0" ixz="0" iyy="0.00000" iyz="0" izz="0.00000"/>
		</inertial>
	</link>
	<link name="left_leg/ffp_8_4">
		<inertial>
			<origin rpy="0.00000 -0.00000 0.00000" xyz="0.00000 0.00000 0.00000"/>
			<mass value="0.00000"/>
			<inertia ixx="0.00000" ixy="0" ixz="0" iyy="0.00000" iyz="0" izz="0.00000"/>
		</inertial>
	</link>
	<link name="left_leg/ffp_9_0">
		<inertial>
			<origin rpy="0.00000 -0.00000 0.00000" xyz="0.00000 0.00000 0.00000"/>
			<mass value="0.00000"/>
			<inertia ixx="0.00000" ixy="0" ixz="0" iyy="0.00000" iyz="0" izz="0.00000"/>
		</inertial>
	</link>
	<link name="left_leg/ffp_9_1">
		<inertial>
			<origin rpy="0.00000 -0.00000 0.00000" xyz="0.00000 0.00000 0.00000"/>
			<mass value="0.00000"/>
			<inertia ixx="0.00000" ixy="0" ixz="0" iyy="0.00000" iyz="0" izz="0.00000"/>
		</inertial>
	</link>
	<link name="left_leg/ffp_9_2">
		<inertial>
			<origin rpy="0.00000 -0.00000 0.00000" xyz="0.00000 0.00000 0.00000"/>
			<mass value="0.00000"/>
			<inertia ixx="0.00000" ixy="0" ixz="0" iyy="0.00000" iyz="0" izz="0.00000"/>
		</inertial>
	</link>
	<link name="left_leg/ffp_9_3">
		<inertial>
			<origin rpy="0.00000 -0.00000 0.00000" xyz="0.00000 0.00000 0.00000"/>
			<mass value="0.00000"/>
			<inertia ixx="0.00000" ixy="0" ixz="0" iyy="0.00000" iyz="0" izz="0.00000"/>
		</inertial>
	</link>
	<link name="left_leg/ffp_9_4">
		<inertial>
			<origin rpy="0.00000 -0.00000 0.00000" xyz="0.00000 0.00000 0.00000"/>
			<mass value="0.00000"/>
			<inertia ixx="0.00000" ixy="0" ixz="0" iyy="0.00000" iyz="0" izz="0.00000"/>
		</inertial>
	</link>
	<link name="right_leg/">
		<inertial>
			<origin rpy="0.00000 -0.00000 0.00000" xyz="0.00000 0.00000 0.00000"/>
			<mass value="0.00000"/>
			<inertia ixx="0.00000" ixy="0" ixz="0" iyy="0.00000" iyz="0" izz="0.00000"/>
		</inertial>
	</link>
	<link name="link1_69">
		<inertial>
			<origin rpy="0.00000 -0.00000 0.00000" xyz="0.00000 0.00000 0.00000"/>
			<mass value="0.00000"/>
			<inertia ixx="0.00000" ixy="0" ixz="0" iyy="0.00000" iyz="0" izz="0.00000"/>
		</inertial>
	</link>
	<link name="link1_70">
		<inertial>
			<origin rpy="0.00000 -0.00000 0.00000" xyz="0.00000 0.00000 0.00000"/>
			<mass value="0.00000"/>
			<inertia ixx="0.00000" ixy="0" ixz="0" iyy="0.00000" iyz="0" izz="0.00000"/>
		</inertial>
	</link>
	<link name="link1_71">
		<inertial>
			<origin rpy="0.00000 -0.00000 0.00000" xyz="0.00000 0.00000 0.00000"/>
			<mass value="0.00000"/>
			<inertia ixx="0.00000" ixy="0" ixz="0" iyy="0.00000" iyz="0" izz="0.00000"/>
		</inertial>
	</link>
	<link name="right_leg/thigh">
		<inertial>
			<origin rpy="0.00000 -0.00000 0.00000" xyz="0.00000 0.00500 -0.14000"/>
			<mass value="4.07352"/>
			<inertia ixx="0.06158" ixy="0" ixz="0" iyy="0.06035" iyz="0" izz="0.01100"/>
		</inertial>
		<collision>
			<origin rpy="-3.10589 -0.00000 0.00000" xyz="0.00000 0.00500 -0.14000"/>
			<geometry>
				<cylinder length="0.28018" radius="0.06000"/>
			</geometry>
		</collision>
	</link>
	<link name="link1_73">
		<inertial>
			<origin rpy="0.00000 -0.00000 0.00000" xyz="0.00000 0.00000 0.00000"/>
			<mass value="0.00000"/>
			<inertia ixx="0.00000" ixy="0" ixz="0" iyy="0.00000" iyz="0" izz="0.00000"/>
		</inertial>
	</link>
	<link name="right_leg/shin">
		<inertial>
			<origin rpy="0.00000 -0.00000 0.00000" xyz="0.00000 0.00000 -0.10100"/>
			<mass value="2.01649"/>
			<inertia ixx="0.01674" ixy="0" ixz="0" iyy="0.01674" iyz="0" izz="0.00323"/>
		</inertial>
		<collision>
			<origin rpy="3.14159 -0.00000 3.14159" xyz="0.00000 0.00000 -0.10100"/>
			<geometry>
				<cylinder length="0.20200" radius="0.04900"/>
			</geometry>
		</collision>
	</link>
	<link name="link1_75">
		<inertial>
			<origin rpy="0.00000 -0.00000 0.00000" xyz="0.00000 0.00000 0.00000"/>
			<mass value="0.00000"/>
			<inertia ixx="0.00000" ixy="0" ixz="0" iyy="0.00000" iyz="0" izz="0.00000"/>
		</inertial>
	</link>
	<link name="link1_76">
		<inertial>
			<origin rpy="0.00000 -0.00000 0.00000" xyz="0.00000 0.00000 0.00000"/>
			<mass value="0.00000"/>
			<inertia ixx="0.00000" ixy="0" ixz="0" iyy="0.00000" iyz="0" izz="0.00000"/>
		</inertial>
	</link>
	<link name="right_leg/foot">
		<inertial>
			<origin rpy="0.00000 -0.00000 0.00000" xyz="0.03500 0.02000 0.00000"/>
			<mass value="1.12679"/>
			<inertia ixx="0.00110" ixy="0" ixz="0" iyy="0.00682" iyz="0" izz="0.00737"/>
		</inertial>
		<collision>
			<origin rpy="0.00000 1.57080 -0.00000" xyz="0.03500 -0.02000 0.00000"/>
			<geometry>
				<cylinder length="0.21000" radius="0.02700"/>
			</geometry>
		</collision>
		<collision>
			<origin rpy="0.00000 1.57080 -0.00000" xyz="0.03500 0.02000 0.00000"/>
			<geometry>
				<cylinder length="0.21000" radius="0.02700"/>
			</geometry>
		</collision>
	</link>
	<link name="right_leg/ffp_0_0">
		<inertial>
			<origin rpy="0.00000 -0.00000 0.00000" xyz="0.00000 0.00000 0.00000"/>
			<mass value="0.00000"/>
			<inertia ixx="0.00000" ixy="0" ixz="0" iyy="0.00000" iyz="0" izz="0.00000"/>
		</inertial>
	</link>
	<link name="right_leg/ffp_0_1">
		<inertial>
			<origin rpy="0.00000 -0.00000 0.00000" xyz="0.00000 0.00000 0.00000"/>
			<mass value="0.00000"/>
			<inertia ixx="0.00000" ixy="0" ixz="0" iyy="0.00000" iyz="0" izz="0.00000"/>
		</inertial>
	</link>
	<link name="right_leg/ffp_0_2">
		<inertial>
			<origin rpy="0.00000 -0.00000 0.00000" xyz="0.00000 0.00000 0.00000"/>
			<mass value="0.00000"/>
			<inertia ixx="0.00000" ixy="0" ixz="0" iyy="0.00000" iyz="0" izz="0.00000"/>
		</inertial>
	</link>
	<link name="right_leg/ffp_0_3">
		<inertial>
			<origin rpy="0.00000 -0.00000 0.00000" xyz="0.00000 0.00000 0.00000"/>
			<mass value="0.00000"/>
			<inertia ixx="0.00000" ixy="0" ixz="0" iyy="0.00000" iyz="0" izz="0.00000"/>
		</inertial>
	</link>
	<link name="right_leg/ffp_0_4">
		<inertial>
			<origin rpy="0.00000 -0.00000 0.00000" xyz="0.00000 0.00000 0.00000"/>
			<mass value="0.00000"/>
			<inertia ixx="0.00000" ixy="0" ixz="0" iyy="0.00000" iyz="0" izz="0.00000"/>
		</inertial>
	</link>
	<link name="right_leg/ffp_1_0">
		<inertial>
			<origin rpy="0.00000 -0.00000 0.00000" xyz="0.00000 0.00000 0.00000"/>
			<mass value="0.00000"/>
			<inertia ixx="0.00000" ixy="0" ixz="0" iyy="0.00000" iyz="0" izz="0.00000"/>
		</inertial>
	</link>
	<link name="right_leg/ffp_1_1">
		<inertial>
			<origin rpy="0.00000 -0.00000 0.00000" xyz="0.00000 0.00000 0.00000"/>
			<mass value="0.00000"/>
			<inertia ixx="0.00000" ixy="0" ixz="0" iyy="0.00000" iyz="0" izz="0.00000"/>
		</inertial>
	</link>
	<link name="right_leg/ffp_1_2">
		<inertial>
			<origin rpy="0.00000 -0.00000 0.00000" xyz="0.00000 0.00000 0.00000"/>
			<mass value="0.00000"/>
			<inertia ixx="0.00000" ixy="0" ixz="0" iyy="0.00000" iyz="0" izz="0.00000"/>
		</inertial>
	</link>
	<link name="right_leg/ffp_1_3">
		<inertial>
			<origin rpy="0.00000 -0.00000 0.00000" xyz="0.00000 0.00000 0.00000"/>
			<mass value="0.00000"/>
			<inertia ixx="0.00000" ixy="0" ixz="0" iyy="0.00000" iyz="0" izz="0.00000"/>
		</inertial>
	</link>
	<link name="right_leg/ffp_1_4">
		<inertial>
			<origin rpy="0.00000 -0.00000 0.00000" xyz="0.00000 0.00000 0.00000"/>
			<mass value="0.00000"/>
			<inertia ixx="0.00000" ixy="0" ixz="0" iyy="0.00000" iyz="0" izz="0.00000"/>
		</inertial>
	</link>
	<link name="right_leg/ffp_2_0">
		<inertial>
			<origin rpy="0.00000 -0.00000 0.00000" xyz="0.00000 0.00000 0.00000"/>
			<mass value="0.00000"/>
			<inertia ixx="0.00000" ixy="0" ixz="0" iyy="0.00000" iyz="0" izz="0.00000"/>
		</inertial>
	</link>
	<link name="right_leg/ffp_2_1">
		<inertial>
			<origin rpy="0.00000 -0.00000 0.00000" xyz="0.00000 0.00000 0.00000"/>
			<mass value="0.00000"/>
			<inertia ixx="0.00000" ixy="0" ixz="0" iyy="0.00000" iyz="0" izz="0.00000"/>
		</inertial>
	</link>
	<link name="right_leg/ffp_2_2">
		<inertial>
			<origin rpy="0.00000 -0.00000 0.00000" xyz="0.00000 0.00000 0.00000"/>
			<mass value="0.00000"/>
			<inertia ixx="0.00000" ixy="0" ixz="0" iyy="0.00000" iyz="0" izz="0.00000"/>
		</inertial>
	</link>
	<link name="right_leg/ffp_2_3">
		<inertial>
			<origin rpy="0.00000 -0.00000 0.00000" xyz="0.00000 0.00000 0.00000"/>
			<mass value="0.00000"/>
			<inertia ixx="0.00000" ixy="0" ixz="0" iyy="0.00000" iyz="0" izz="0.00000"/>
		</inertial>
	</link>
	<link name="right_leg/ffp_2_4">
		<inertial>
			<origin rpy="0.00000 -0.00000 0.00000" xyz="0.00000 0.00000 0.00000"/>
			<mass value="0.00000"/>
			<inertia ixx="0.00000" ixy="0" ixz="0" iyy="0.00000" iyz="0" izz="0.00000"/>
		</inertial>
	</link>
	<link name="right_leg/ffp_3_0">
		<inertial>
			<origin rpy="0.00000 -0.00000 0.00000" xyz="0.00000 0.00000 0.00000"/>
			<mass value="0.00000"/>
			<inertia ixx="0.00000" ixy="0" ixz="0" iyy="0.00000" iyz="0" izz="0.00000"/>
		</inertial>
	</link>
	<link name="right_leg/ffp_3_1">
		<inertial>
			<origin rpy="0.00000 -0.00000 0.00000" xyz="0.00000 0.00000 0.00000"/>
			<mass value="0.00000"/>
			<inertia ixx="0.00000" ixy="0" ixz="0" iyy="0.00000" iyz="0" izz="0.00000"/>
		</inertial>
	</link>
	<link name="right_leg/ffp_3_2">
		<inertial>
			<origin rpy="0.00000 -0.00000 0.00000" xyz="0.00000 0.00000 0.00000"/>
			<mass value="0.00000"/>
			<inertia ixx="0.00000" ixy="0" ixz="0" iyy="0.00000" iyz="0" izz="0.00000"/>
		</inertial>
	</link>
	<link name="right_leg/ffp_3_3">
		<inertial>
			<origin rpy="0.00000 -0.00000 0.00000" xyz="0.00000 0.00000 0.00000"/>
			<mass value="0.00000"/>
			<inertia ixx="0.00000" ixy="0" ixz="0" iyy="0.00000" iyz="0" izz="0.00000"/>
		</inertial>
	</link>
	<link name="right_leg/ffp_3_4">
		<inertial>
			<origin rpy="0.00000 -0.00000 0.00000" xyz="0.00000 0.00000 0.00000"/>
			<mass value="0.00000"/>
			<inertia ixx="0.00000" ixy="0" ixz="0" iyy="0.00000" iyz="0" izz="0.00000"/>
		</inertial>
	</link>
	<link name="right_leg/ffp_4_0">
		<inertial>
			<origin rpy="0.00000 -0.00000 0.00000" xyz="0.00000 0.00000 0.00000"/>
			<mass value="0.00000"/>
			<inertia ixx="0.00000" ixy="0" ixz="0" iyy="0.00000" iyz="0" izz="0.00000"/>
		</inertial>
	</link>
	<link name="right_leg/ffp_4_1">
		<inertial>
			<origin rpy="0.00000 -0.00000 0.00000" xyz="0.00000 0.00000 0.00000"/>
			<mass value="0.00000"/>
			<inertia ixx="0.00000" ixy="0" ixz="0" iyy="0.00000" iyz="0" izz="0.00000"/>
		</inertial>
	</link>
	<link name="right_leg/ffp_4_2">
		<inertial>
			<origin rpy="0.00000 -0.00000 0.00000" xyz="0.00000 0.00000 0.00000"/>
			<mass value="0.00000"/>
			<inertia ixx="0.00000" ixy="0" ixz="0" iyy="0.00000" iyz="0" izz="0.00000"/>
		</inertial>
	</link>
	<link name="right_leg/ffp_4_3">
		<inertial>
			<origin rpy="0.00000 -0.00000 0.00000" xyz="0.00000 0.00000 0.00000"/>
			<mass value="0.00000"/>
			<inertia ixx="0.00000" ixy="0" ixz="0" iyy="0.00000" iyz="0" izz="0.00000"/>
		</inertial>
	</link>
	<link name="right_leg/ffp_4_4">
		<inertial>
			<origin rpy="0.00000 -0.00000 0.00000" xyz="0.00000 0.00000 0.00000"/>
			<mass value="0.00000"/>
			<inertia ixx="0.00000" ixy="0" ixz="0" iyy="0.00000" iyz="0" izz="0.00000"/>
		</inertial>
	</link>
	<link name="right_leg/ffp_5_0">
		<inertial>
			<origin rpy="0.00000 -0.00000 0.00000" xyz="0.00000 0.00000 0.00000"/>
			<mass value="0.00000"/>
			<inertia ixx="0.00000" ixy="0" ixz="0" iyy="0.00000" iyz="0" izz="0.00000"/>
		</inertial>
	</link>
	<link name="right_leg/ffp_5_1">
		<inertial>
			<origin rpy="0.00000 -0.00000 0.00000" xyz="0.00000 0.00000 0.00000"/>
			<mass value="0.00000"/>
			<inertia ixx="0.00000" ixy="0" ixz="0" iyy="0.00000" iyz="0" izz="0.00000"/>
		</inertial>
	</link>
	<link name="right_leg/ffp_5_2">
		<inertial>
			<origin rpy="0.00000 -0.00000 0.00000" xyz="0.00000 0.00000 0.00000"/>
			<mass value="0.00000"/>
			<inertia ixx="0.00000" ixy="0" ixz="0" iyy="0.00000" iyz="0" izz="0.00000"/>
		</inertial>
	</link>
	<link name="right_leg/ffp_5_3">
		<inertial>
			<origin rpy="0.00000 -0.00000 0.00000" xyz="0.00000 0.00000 0.00000"/>
			<mass value="0.00000"/>
			<inertia ixx="0.00000" ixy="0" ixz="0" iyy="0.00000" iyz="0" izz="0.00000"/>
		</inertial>
	</link>
	<link name="right_leg/ffp_5_4">
		<inertial>
			<origin rpy="0.00000 -0.00000 0.00000" xyz="0.00000 0.00000 0.00000"/>
			<mass value="0.00000"/>
			<inertia ixx="0.00000" ixy="0" ixz="0" iyy="0.00000" iyz="0" izz="0.00000"/>
		</inertial>
	</link>
	<link name="right_leg/ffp_6_0">
		<inertial>
			<origin rpy="0.00000 -0.00000 0.00000" xyz="0.00000 0.00000 0.00000"/>
			<mass value="0.00000"/>
			<inertia ixx="0.00000" ixy="0" ixz="0" iyy="0.00000" iyz="0" izz="0.00000"/>
		</inertial>
	</link>
	<link name="right_leg/ffp_6_1">
		<inertial>
			<origin rpy="0.00000 -0.00000 0.00000" xyz="0.00000 0.00000 0.00000"/>
			<mass value="0.00000"/>
			<inertia ixx="0.00000" ixy="0" ixz="0" iyy="0.00000" iyz="0" izz="0.00000"/>
		</inertial>
	</link>
	<link name="right_leg/ffp_6_2">
		<inertial>
			<origin rpy="0.00000 -0.00000 0.00000" xyz="0.00000 0.00000 0.00000"/>
			<mass value="0.00000"/>
			<inertia ixx="0.00000" ixy="0" ixz="0" iyy="0.00000" iyz="0" izz="0.00000"/>
		</inertial>
	</link>
	<link name="right_leg/ffp_6_3">
		<inertial>
			<origin rpy="0.00000 -0.00000 0.00000" xyz="0.00000 0.00000 0.00000"/>
			<mass value="0.00000"/>
			<inertia ixx="0.00000" ixy="0" ixz="0" iyy="0.00000" iyz="0" izz="0.00000"/>
		</inertial>
	</link>
	<link name="right_leg/ffp_6_4">
		<inertial>
			<origin rpy="0.00000 -0.00000 0.00000" xyz="0.00000 0.00000 0.00000"/>
			<mass value="0.00000"/>
			<inertia ixx="0.00000" ixy="0" ixz="0" iyy="0.00000" iyz="0" izz="0.00000"/>
		</inertial>
	</link>
	<link name="right_leg/ffp_7_0">
		<inertial>
			<origin rpy="0.00000 -0.00000 0.00000" xyz="0.00000 0.00000 0.00000"/>
			<mass value="0.00000"/>
			<inertia ixx="0.00000" ixy="0" ixz="0" iyy="0.00000" iyz="0" izz="0.00000"/>
		</inertial>
	</link>
	<link name="right_leg/ffp_7_1">
		<inertial>
			<origin rpy="0.00000 -0.00000 0.00000" xyz="0.00000 0.00000 0.00000"/>
			<mass value="0.00000"/>
			<inertia ixx="0.00000" ixy="0" ixz="0" iyy="0.00000" iyz="0" izz="0.00000"/>
		</inertial>
	</link>
	<link name="right_leg/ffp_7_2">
		<inertial>
			<origin rpy="0.00000 -0.00000 0.00000" xyz="0.00000 0.00000 0.00000"/>
			<mass value="0.00000"/>
			<inertia ixx="0.00000" ixy="0" ixz="0" iyy="0.00000" iyz="0" izz="0.00000"/>
		</inertial>
	</link>
	<link name="right_leg/ffp_7_3">
		<inertial>
			<origin rpy="0.00000 -0.00000 0.00000" xyz="0.00000 0.00000 0.00000"/>
			<mass value="0.00000"/>
			<inertia ixx="0.00000" ixy="0" ixz="0" iyy="0.00000" iyz="0" izz="0.00000"/>
		</inertial>
	</link>
	<link name="right_leg/ffp_7_4">
		<inertial>
			<origin rpy="0.00000 -0.00000 0.00000" xyz="0.00000 0.00000 0.00000"/>
			<mass value="0.00000"/>
			<inertia ixx="0.00000" ixy="0" ixz="0" iyy="0.00000" iyz="0" izz="0.00000"/>
		</inertial>
	</link>
	<link name="right_leg/ffp_8_0">
		<inertial>
			<origin rpy="0.00000 -0.00000 0.00000" xyz="0.00000 0.00000 0.00000"/>
			<mass value="0.00000"/>
			<inertia ixx="0.00000" ixy="0" ixz="0" iyy="0.00000" iyz="0" izz="0.00000"/>
		</inertial>
	</link>
	<link name="right_leg/ffp_8_1">
		<inertial>
			<origin rpy="0.00000 -0.00000 0.00000" xyz="0.00000 0.00000 0.00000"/>
			<mass value="0.00000"/>
			<inertia ixx="0.00000" ixy="0" ixz="0" iyy="0.00000" iyz="0" izz="0.00000"/>
		</inertial>
	</link>
	<link name="right_leg/ffp_8_2">
		<inertial>
			<origin rpy="0.00000 -0.00000 0.00000" xyz="0.00000 0.00000 0.00000"/>
			<mass value="0.00000"/>
			<inertia ixx="0.00000" ixy="0" ixz="0" iyy="0.00000" iyz="0" izz="0.00000"/>
		</inertial>
	</link>
	<link name="right_leg/ffp_8_3">
		<inertial>
			<origin rpy="0.00000 -0.00000 0.00000" xyz="0.00000 0.00000 0.00000"/>
			<mass value="0.00000"/>
			<inertia ixx="0.00000" ixy="0" ixz="0" iyy="0.00000" iyz="0" izz="0.00000"/>
		</inertial>
	</link>
	<link name="right_leg/ffp_8_4">
		<inertial>
			<origin rpy="0.00000 -0.00000 0.00000" xyz="0.00000 0.00000 0.00000"/>
			<mass value="0.00000"/>
			<inertia ixx="0.00000" ixy="0" ixz="0" iyy="0.00000" iyz="0" izz="0.00000"/>
		</inertial>
	</link>
	<link name="right_leg/ffp_9_0">
		<inertial>
			<origin rpy="0.00000 -0.00000 0.00000" xyz="0.00000 0.00000 0.00000"/>
			<mass value="0.00000"/>
			<inertia ixx="0.00000" ixy="0" ixz="0" iyy="0.00000" iyz="0" izz="0.00000"/>
		</inertial>
	</link>
	<link name="right_leg/ffp_9_1">
		<inertial>
			<origin rpy="0.00000 -0.00000 0.00000" xyz="0.00000 0.00000 0.00000"/>
			<mass value="0.00000"/>
			<inertia ixx="0.00000" ixy="0" ixz="0" iyy="0.00000" iyz="0" izz="0.00000"/>
		</inertial>
	</link>
	<link name="right_leg/ffp_9_2">
		<inertial>
			<origin rpy="0.00000 -0.00000 0.00000" xyz="0.00000 0.00000 0.00000"/>
			<mass value="0.00000"/>
			<inertia ixx="0.00000" ixy="0" ixz="0" iyy="0.00000" iyz="0" izz="0.00000"/>
		</inertial>
	</link>
	<link name="right_leg/ffp_9_3">
		<inertial>
			<origin rpy="0.00000 -0.00000 0.00000" xyz="0.00000 0.00000 0.00000"/>
			<mass value="0.00000"/>
			<inertia ixx="0.00000" ixy="0" ixz="0" iyy="0.00000" iyz="0" izz="0.00000"/>
		</inertial>
	</link>
	<link name="right_leg/ffp_9_4">
		<inertial>
			<origin rpy="0.00000 -0.00000 0.00000" xyz="0.00000 0.00000 0.00000"/>
			<mass value="0.00000"/>
			<inertia ixx="0.00000" ixy="0" ixz="0" iyy="0.00000" iyz="0" izz="0.00000"/>
		</inertial>
	</link>
	<joint name="jointfix_0_0" type="fixed">
		<parent link="torso"/>
		<child link="head"/>
		<dynamics damping="1.0" friction="0.0001"/>
		<origin rpy="0.00000 -0.00000 0.00000" xyz="0.00000 0.00000 0.19000"/>
		<axis xyz="0.00000 0.00000 0.00000"/>
	</joint>
	<joint name="abdomen_z" type="revolute">
		<parent link="torso"/>
		<child link="link1_3"/>
		<limit effort="0.00000" lower="-45.00000" upper="45.00000" velocity="0.00000"/>
		<dynamics damping="1.0" friction="0.0001"/>
		<origin rpy="0.00000 -0.00400 0.00000" xyz="-0.01026 0.00000 -0.19500"/>
		<axis xyz="0.00000 0.00000 1.00000"/>
	</joint>
	<joint name="abdomen_y" type="revolute">
		<parent link="link1_3"/>
		<child link="link1_4"/>
		<limit effort="0.00000" lower="-75.00000" upper="30.00000" velocity="0.00000"/>
		<dynamics damping="1.0" friction="0.0001"/>
		<origin rpy="0.00000 -0.00000 0.00000" xyz="0.00000 0.00000 0.00000"/>
		<axis xyz="0.00000 1.00000 0.00000"/>
	</joint>
	<joint name="jointfix_110_4" type="fixed">
		<parent link="link1_4"/>
		<child link="lower_waist"/>
		<dynamics damping="1.0" friction="0.0001"/>
		<origin rpy="0.00000 -0.00000 0.00000" xyz="0.00000 0.00000 -0.06500"/>
		<axis xyz="0.00000 0.00000 0.00000"/>
	</joint>
	<joint name="abdomen_x" type="revolute">
		<parent link="lower_waist"/>
		<child link="link1_6"/>
		<limit effort="0.00000" lower="-35.00000" upper="35.00000" velocity="0.00000"/>
		<dynamics damping="1.0" friction="0.0001"/>
		<origin rpy="0.00000 -0.00400 0.00000" xyz="-0.00040 0.00000 -0.06500"/>
		<axis xyz="1.00000 0.00000 0.00000"/>
	</joint>
	<joint name="jointfix_109_6" type="fixed">
		<parent link="link1_6"/>
		<child link="pelvis"/>
		<dynamics damping="1.0" friction="0.0001"/>
		<origin rpy="0.00000 -0.00000 0.00000" xyz="0.00000 0.00000 -0.10000"/>
		<axis xyz="0.00000 0.00000 0.00000"/>
	</joint>
	<joint name="jointfix_54_5" type="fixed">
		<parent link="pelvis"/>
		<child link="left_leg/"/>
		<dynamics damping="1.0" friction="0.0001"/>
		<origin rpy="0.00000 -0.00000 0.00000" xyz="0.00000 0.10000 -0.04000"/>
		<axis xyz="0.00000 0.00000 0.00000"/>
	</joint>
	<joint name="left_leg/hip_x" type="revolute">
		<parent link="left_leg/"/>
		<child link="link1_9"/>
		<limit effort="0.00000" lower="-25.00000" upper="5.00000" velocity="0.00000"/>
		<dynamics damping="1.0" friction="0.0001"/>
		<origin rpy="0.00000 -0.00000 0.00000" xyz="0.00000 0.00000 0.00000"/>
		<axis xyz="1.00000 0.00000 0.00000"/>
	</joint>
	<joint name="left_leg/hip_z" type="revolute">
		<parent link="link1_9"/>
		<child link="link1_10"/>
		<limit effort="0.00000" lower="-60.00000" upper="35.00000" velocity="0.00000"/>
		<dynamics damping="1.0" friction="0.0001"/>
		<origin rpy="0.00000 -0.00000 0.00000" xyz="0.00000 0.00000 0.00000"/>
		<axis xyz="0.00000 0.00000 1.00000"/>
	</joint>
	<joint name="left_leg/hip_y" type="revolute">
		<parent link="link1_10"/>
		<child link="link1_11"/>
		<limit effort="0.00000" lower="-110.00000" upper="20.00000" velocity="0.00000"/>
		<dynamics damping="1.0" friction="0.0001"/>
		<origin rpy="0.00000 -0.00000 0.00000" xyz="0.00000 0.00000 0.00000"/>
		<axis xyz="0.00000 1.00000 0.00000"/>
	</joint>
	<joint name="jointfix_53_11" type="fixed">
		<parent link="link1_11"/>
		<child link="left_leg/thigh"/>
		<dynamics damping="1.0" friction="0.0001"/>
		<origin rpy="0.00000 -0.00000 0.00000" xyz="0.00000 0.00000 0.00000"/>
		<axis xyz="0.00000 0.00000 0.00000"/>
	</joint>
	<joint name="left_leg/knee" type="revolute">
		<parent link="left_leg/thigh"/>
		<child link="link1_13"/>
		<limit effort="0.00000" lower="-160.00000" upper="2.00000" velocity="0.00000"/>
		<dynamics damping="1.0" friction="0.0001"/>
		<origin rpy="0.00000 -0.00000 0.00000" xyz="0.00000 -0.01000 -0.32300"/>
		<axis xyz="0.00000 -1.00000 0.00000"/>
	</joint>
	<joint name="jointfix_52_13" type="fixed">
		<parent link="link1_13"/>
		<child link="left_leg/shin"/>
		<dynamics damping="1.0" friction="0.0001"/>
		<origin rpy="0.00000 -0.00000 0.00000" xyz="0.00000 0.00000 -0.02000"/>
		<axis xyz="0.00000 0.00000 0.00000"/>
	</joint>
	<joint name="left_leg/ankle_y" type="revolute">
		<parent link="left_leg/shin"/>
		<child link="link1_15"/>
		<limit effort="0.00000" lower="-50.00000" upper="50.00000" velocity="0.00000"/>
		<dynamics damping="1.0" friction="0.0001"/>
		<origin rpy="0.00000 -0.00000 0.00000" xyz="0.00000 0.00000 -0.21200"/>
		<axis xyz="0.00000 1.00000 0.00000"/>
	</joint>
	<joint name="left_leg/ankle_x" type="revolute">
		<parent link="link1_15"/>
		<child link="link1_16"/>
		<limit effort="0.00000" lower="-50.00000" upper="50.00000" velocity="0.00000"/>
		<dynamics damping="1.0" friction="0.0001"/>
		<origin rpy="0.00000 -0.00000 0.00000" xyz="0.00000 0.00000 -0.04000"/>
		<axis xyz="1.00000 0.00000 0.50000"/>
	</joint>
	<joint name="jointfix_51_16" type="fixed">
		<parent link="link1_16"/>
		<child link="left_leg/foot"/>
		<dynamics damping="1.0" friction="0.0001"/>
		<origin rpy="0.00000 -0.00000 0.00000" xyz="0.00000 0.00000 -0.08000"/>
		<axis xyz="0.00000 0.00000 0.00000"/>
	</joint>
	<joint name="jointfix_1_14" type="fixed">
		<parent link="left_leg/foot"/>
		<child link="left_leg/ffp_0_0"/>
		<dynamics damping="1.0" friction="0.0001"/>
		<origin rpy="0.00000 -0.00000 0.00000" xyz="-0.07000 -0.04700 -0.02700"/>
		<axis xyz="0.00000 0.00000 0.00000"/>
	</joint>
	<joint name="jointfix_2_14" type="fixed">
		<parent link="left_leg/foot"/>
		<child link="left_leg/ffp_0_1"/>
		<dynamics damping="1.0" friction="0.0001"/>
		<origin rpy="0.00000 -0.00000 0.00000" xyz="-0.07000 -0.02540 -0.02700"/>
		<axis xyz="0.00000 0.00000 0.00000"/>
	</joint>
	<joint name="jointfix_3_14" type="fixed">
		<parent link="left_leg/foot"/>
		<child link="left_leg/ffp_0_2"/>
		<dynamics damping="1.0" friction="0.0001"/>
		<origin rpy="0.00000 -0.00000 0.00000" xyz="-0.07000 -0.00380 -0.02700"/>
		<axis xyz="0.00000 0.00000 0.00000"/>
	</joint>
	<joint name="jointfix_4_14" type="fixed">
		<parent link="left_leg/foot"/>
		<child link="left_leg/ffp_0_3"/>
		<dynamics damping="1.0" friction="0.0001"/>
		<origin rpy="0.00000 -0.00000 0.00000" xyz="-0.07000 0.01780 -0.02700"/>
		<axis xyz="0.00000 0.00000 0.00000"/>
	</joint>
	<joint name="jointfix_5_14" type="fixed">
		<parent link="left_leg/foot"/>
		<child link="left_leg/ffp_0_4"/>
		<dynamics damping="1.0" friction="0.0001"/>
		<origin rpy="0.00000 -0.00000 0.00000" xyz="-0.07000 0.03940 -0.02700"/>
		<axis xyz="0.00000 0.00000 0.00000"/>
	</joint>
	<joint name="jointfix_6_14" type="fixed">
		<parent link="left_leg/foot"/>
		<child link="left_leg/ffp_1_0"/>
		<dynamics damping="1.0" friction="0.0001"/>
		<origin rpy="0.00000 -0.00000 0.00000" xyz="-0.04900 -0.04700 -0.02700"/>
		<axis xyz="0.00000 0.00000 0.00000"/>
	</joint>
	<joint name="jointfix_7_14" type="fixed">
		<parent link="left_leg/foot"/>
		<child link="left_leg/ffp_1_1"/>
		<dynamics damping="1.0" friction="0.0001"/>
		<origin rpy="0.00000 -0.00000 0.00000" xyz="-0.04900 -0.02540 -0.02700"/>
		<axis xyz="0.00000 0.00000 0.00000"/>
	</joint>
	<joint name="jointfix_8_14" type="fixed">
		<parent link="left_leg/foot"/>
		<child link="left_leg/ffp_1_2"/>
		<dynamics damping="1.0" friction="0.0001"/>
		<origin rpy="0.00000 -0.00000 0.00000" xyz="-0.04900 -0.00380 -0.02700"/>
		<axis xyz="0.00000 0.00000 0.00000"/>
	</joint>
	<joint name="jointfix_9_14" type="fixed">
		<parent link="left_leg/foot"/>
		<child link="left_leg/ffp_1_3"/>
		<dynamics damping="1.0" friction="0.0001"/>
		<origin rpy="0.00000 -0.00000 0.00000" xyz="-0.04900 0.01780 -0.02700"/>
		<axis xyz="0.00000 0.00000 0.00000"/>
	</joint>
	<joint name="jointfix_10_14" type="fixed">
		<parent link="left_leg/foot"/>
		<child link="left_leg/ffp_1_4"/>
		<dynamics damping="1.0" friction="0.0001"/>
		<origin rpy="0.00000 -0.00000 0.00000" xyz="-0.04900 0.03940 -0.02700"/>
		<axis xyz="0.00000 0.00000 0.00000"/>
	</joint>
	<joint name="jointfix_11_14" type="fixed">
		<parent link="left_leg/foot"/>
		<child link="left_leg/ffp_2_0"/>
		<dynamics damping="1.0" friction="0.0001"/>
		<origin rpy="0.00000 -0.00000 0.00000" xyz="-0.02800 -0.04700 -0.02700"/>
		<axis xyz="0.00000 0.00000 0.00000"/>
	</joint>
	<joint name="jointfix_12_14" type="fixed">
		<parent link="left_leg/foot"/>
		<child link="left_leg/ffp_2_1"/>
		<dynamics damping="1.0" friction="0.0001"/>
		<origin rpy="0.00000 -0.00000 0.00000" xyz="-0.02800 -0.02540 -0.02700"/>
		<axis xyz="0.00000 0.00000 0.00000"/>
	</joint>
	<joint name="jointfix_13_14" type="fixed">
		<parent link="left_leg/foot"/>
		<child link="left_leg/ffp_2_2"/>
		<dynamics damping="1.0" friction="0.0001"/>
		<origin rpy="0.00000 -0.00000 0.00000" xyz="-0.02800 -0.00380 -0.02700"/>
		<axis xyz="0.00000 0.00000 0.00000"/>
	</joint>
	<joint name="jointfix_14_14" type="fixed">
		<parent link="left_leg/foot"/>
		<child link="left_leg/ffp_2_3"/>
		<dynamics damping="1.0" friction="0.0001"/>
		<origin rpy="0.00000 -0.00000 0.00000" xyz="-0.02800 0.01780 -0.02700"/>
		<axis xyz="0.00000 0.00000 0.00000"/>
	</joint>
	<joint name="jointfix_15_14" type="fixed">
		<parent link="left_leg/foot"/>
		<child link="left_leg/ffp_2_4"/>
		<dynamics damping="1.0" friction="0.0001"/>
		<origin rpy="0.00000 -0.00000 0.00000" xyz="-0.02800 0.03940 -0.02700"/>
		<axis xyz="0.00000 0.00000 0.00000"/>
	</joint>
	<joint name="jointfix_16_14" type="fixed">
		<parent link="left_leg/foot"/>
		<child link="left_leg/ffp_3_0"/>
		<dynamics damping="1.0" friction="0.0001"/>
		<origin rpy="0.00000 -0.00000 0.00000" xyz="-0.00700 -0.04700 -0.02700"/>
		<axis xyz="0.00000 0.00000 0.00000"/>
	</joint>
	<joint name="jointfix_17_14" type="fixed">
		<parent link="left_leg/foot"/>
		<child link="left_leg/ffp_3_1"/>
		<dynamics damping="1.0" friction="0.0001"/>
		<origin rpy="0.00000 -0.00000 0.00000" xyz="-0.00700 -0.02540 -0.02700"/>
		<axis xyz="0.00000 0.00000 0.00000"/>
	</joint>
	<joint name="jointfix_18_14" type="fixed">
		<parent link="left_leg/foot"/>
		<child link="left_leg/ffp_3_2"/>
		<dynamics damping="1.0" friction="0.0001"/>
		<origin rpy="0.00000 -0.00000 0.00000" xyz="-0.00700 -0.00380 -0.02700"/>
		<axis xyz="0.00000 0.00000 0.00000"/>
	</joint>
	<joint name="jointfix_19_14" type="fixed">
		<parent link="left_leg/foot"/>
		<child link="left_leg/ffp_3_3"/>
		<dynamics damping="1.0" friction="0.0001"/>
		<origin rpy="0.00000 -0.00000 0.00000" xyz="-0.00700 0.01780 -0.02700"/>
		<axis xyz="0.00000 0.00000 0.00000"/>
	</joint>
	<joint name="jointfix_20_14" type="fixed">
		<parent link="left_leg/foot"/>
		<child link="left_leg/ffp_3_4"/>
		<dynamics damping="1.0" friction="0.0001"/>
		<origin rpy="0.00000 -0.00000 0.00000" xyz="-0.00700 0.03940 -0.02700"/>
		<axis xyz="0.00000 0.00000 0.00000"/>
	</joint>
	<joint name="jointfix_21_14" type="fixed">
		<parent link="left_leg/foot"/>
		<child link="left_leg/ffp_4_0"/>
		<dynamics damping="1.0" friction="0.0001"/>
		<origin rpy="0.00000 -0.00000 0.00000" xyz="0.01400 -0.04700 -0.02700"/>
		<axis xyz="0.00000 0.00000 0.00000"/>
	</joint>
	<joint name="jointfix_22_14" type="fixed">
		<parent link="left_leg/foot"/>
		<child link="left_leg/ffp_4_1"/>
		<dynamics damping="1.0" friction="0.0001"/>
		<origin rpy="0.00000 -0.00000 0.00000" xyz="0.01400 -0.02540 -0.02700"/>
		<axis xyz="0.00000 0.00000 0.00000"/>
	</joint>
	<joint name="jointfix_23_14" type="fixed">
		<parent link="left_leg/foot"/>
		<child link="left_leg/ffp_4_2"/>
		<dynamics damping="1.0" friction="0.0001"/>
		<origin rpy="0.00000 -0.00000 0.00000" xyz="0.01400 -0.00380 -0.02700"/>
		<axis xyz="0.00000 0.00000 0.00000"/>
	</joint>
	<joint name="jointfix_24_14" type="fixed">
		<parent link="left_leg/foot"/>
		<child link="left_leg/ffp_4_3"/>
		<dynamics damping="1.0" friction="0.0001"/>
		<origin rpy="0.00000 -0.00000 0.00000" xyz="0.01400 0.01780 -0.02700"/>
		<axis xyz="0.00000 0.00000 0.00000"/>
	</joint>
	<joint name="jointfix_25_14" type="fixed">
		<parent link="left_leg/foot"/>
		<child link="left_leg/ffp_4_4"/>
		<dynamics damping="1.0" friction="0.0001"/>
		<origin rpy="0.00000 -0.00000 0.00000" xyz="0.01400 0.03940 -0.02700"/>
		<axis xyz="0.00000 0.00000 0.00000"/>
	</joint>
	<joint name="jointfix_26_14" type="fixed">
		<parent link="left_leg/foot"/>
		<child link="left_leg/ffp_5_0"/>
		<dynamics damping="1.0" friction="0.0001"/>
		<origin rpy="0.00000 -0.00000 0.00000" xyz="0.03500 -0.04700 -0.02700"/>
		<axis xyz="0.00000 0.00000 0.00000"/>
	</joint>
	<joint name="jointfix_27_14" type="fixed">
		<parent link="left_leg/foot"/>
		<child link="left_leg/ffp_5_1"/>
		<dynamics damping="1.0" friction="0.0001"/>
		<origin rpy="0.00000 -0.00000 0.00000" xyz="0.03500 -0.02540 -0.02700"/>
		<axis xyz="0.00000 0.00000 0.00000"/>
	</joint>
	<joint name="jointfix_28_14" type="fixed">
		<parent link="left_leg/foot"/>
		<child link="left_leg/ffp_5_2"/>
		<dynamics damping="1.0" friction="0.0001"/>
		<origin rpy="0.00000 -0.00000 0.00000" xyz="0.03500 -0.00380 -0.02700"/>
		<axis xyz="0.00000 0.00000 0.00000"/>
	</joint>
	<joint name="jointfix_29_14" type="fixed">
		<parent link="left_leg/foot"/>
		<child link="left_leg/ffp_5_3"/>
		<dynamics damping="1.0" friction="0.0001"/>
		<origin rpy="0.00000 -0.00000 0.00000" xyz="0.03500 0.01780 -0.02700"/>
		<axis xyz="0.00000 0.00000 0.00000"/>
	</joint>
	<joint name="jointfix_30_14" type="fixed">
		<parent link="left_leg/foot"/>
		<child link="left_leg/ffp_5_4"/>
		<dynamics damping="1.0" friction="0.0001"/>
		<origin rpy="0.00000 -0.00000 0.00000" xyz="0.03500 0.03940 -0.02700"/>
		<axis xyz="0.00000 0.00000 0.00000"/>
	</joint>
	<joint name="jointfix_31_14" type="fixed">
		<parent link="left_leg/foot"/>
		<child link="left_leg/ffp_6_0"/>
		<dynamics damping="1.0" friction="0.0001"/>
		<origin rpy="0.00000 -0.00000 0.00000" xyz="0.05600 -0.04700 -0.02700"/>
		<axis xyz="0.00000 0.00000 0.00000"/>
	</joint>
	<joint name="jointfix_32_14" type="fixed">
		<parent link="left_leg/foot"/>
		<child link="left_leg/ffp_6_1"/>
		<dynamics damping="1.0" friction="0.0001"/>
		<origin rpy="0.00000 -0.00000 0.00000" xyz="0.05600 -0.02540 -0.02700"/>
		<axis xyz="0.00000 0.00000 0.00000"/>
	</joint>
	<joint name="jointfix_33_14" type="fixed">
		<parent link="left_leg/foot"/>
		<child link="left_leg/ffp_6_2"/>
		<dynamics damping="1.0" friction="0.0001"/>
		<origin rpy="0.00000 -0.00000 0.00000" xyz="0.05600 -0.00380 -0.02700"/>
		<axis xyz="0.00000 0.00000 0.00000"/>
	</joint>
	<joint name="jointfix_34_14" type="fixed">
		<parent link="left_leg/foot"/>
		<child link="left_leg/ffp_6_3"/>
		<dynamics damping="1.0" friction="0.0001"/>
		<origin rpy="0.00000 -0.00000 0.00000" xyz="0.05600 0.01780 -0.02700"/>
		<axis xyz="0.00000 0.00000 0.00000"/>
	</joint>
	<joint name="jointfix_35_14" type="fixed">
		<parent link="left_leg/foot"/>
		<child link="left_leg/ffp_6_4"/>
		<dynamics damping="1.0" friction="0.0001"/>
		<origin rpy="0.00000 -0.00000 0.00000" xyz="0.05600 0.03940 -0.02700"/>
		<axis xyz="0.00000 0.00000 0.00000"/>
	</joint>
	<joint name="jointfix_36_14" type="fixed">
		<parent link="left_leg/foot"/>
		<child link="left_leg/ffp_7_0"/>
		<dynamics damping="1.0" friction="0.0001"/>
		<origin rpy="0.00000 -0.00000 0.00000" xyz="0.07700 -0.04700 -0.02700"/>
		<axis xyz="0.00000 0.00000 0.00000"/>
	</joint>
	<joint name="jointfix_37_14" type="fixed">
		<parent link="left_leg/foot"/>
		<child link="left_leg/ffp_7_1"/>
		<dynamics damping="1.0" friction="0.0001"/>
		<origin rpy="0.00000 -0.00000 0.00000" xyz="0.07700 -0.02540 -0.02700"/>
		<axis xyz="0.00000 0.00000 0.00000"/>
	</joint>
	<joint name="jointfix_38_14" type="fixed">
		<parent link="left_leg/foot"/>
		<child link="left_leg/ffp_7_2"/>
		<dynamics damping="1.0" friction="0.0001"/>
		<origin rpy="0.00000 -0.00000 0.00000" xyz="0.07700 -0.00380 -0.02700"/>
		<axis xyz="0.00000 0.00000 0.00000"/>
	</joint>
	<joint name="jointfix_39_14" type="fixed">
		<parent link="left_leg/foot"/>
		<child link="left_leg/ffp_7_3"/>
		<dynamics damping="1.0" friction="0.0001"/>
		<origin rpy="0.00000 -0.00000 0.00000" xyz="0.07700 0.01780 -0.02700"/>
		<axis xyz="0.00000 0.00000 0.00000"/>
	</joint>
	<joint name="jointfix_40_14" type="fixed">
		<parent link="left_leg/foot"/>
		<child link="left_leg/ffp_7_4"/>
		<dynamics damping="1.0" friction="0.0001"/>
		<origin rpy="0.00000 -0.00000 0.00000" xyz="0.07700 0.03940 -0.02700"/>
		<axis xyz="0.00000 0.00000 0.00000"/>
	</joint>
	<joint name="jointfix_41_14" type="fixed">
		<parent link="left_leg/foot"/>
		<child link="left_leg/ffp_8_0"/>
		<dynamics damping="1.0" friction="0.0001"/>
		<origin rpy="0.00000 -0.00000 0.00000" xyz="0.09800 -0.04700 -0.02700"/>
		<axis xyz="0.00000 0.00000 0.00000"/>
	</joint>
	<joint name="jointfix_42_14" type="fixed">
		<parent link="left_leg/foot"/>
		<child link="left_leg/ffp_8_1"/>
		<dynamics damping="1.0" friction="0.0001"/>
		<origin rpy="0.00000 -0.00000 0.00000" xyz="0.09800 -0.02540 -0.02700"/>
		<axis xyz="0.00000 0.00000 0.00000"/>
	</joint>
	<joint name="jointfix_43_14" type="fixed">
		<parent link="left_leg/foot"/>
		<child link="left_leg/ffp_8_2"/>
		<dynamics damping="1.0" friction="0.0001"/>
		<origin rpy="0.00000 -0.00000 0.00000" xyz="0.09800 -0.00380 -0.02700"/>
		<axis xyz="0.00000 0.00000 0.00000"/>
	</joint>
	<joint name="jointfix_44_14" type="fixed">
		<parent link="left_leg/foot"/>
		<child link="left_leg/ffp_8_3"/>
		<dynamics damping="1.0" friction="0.0001"/>
		<origin rpy="0.00000 -0.00000 0.00000" xyz="0.09800 0.01780 -0.02700"/>
		<axis xyz="0.00000 0.00000 0.00000"/>
	</joint>
	<joint name="jointfix_45_14" type="fixed">
		<parent link="left_leg/foot"/>
		<child link="left_leg/ffp_8_4"/>
		<dynamics damping="1.0" friction="0.0001"/>
		<origin rpy="0.00000 -0.00000 0.00000" xyz="0.09800 0.03940 -0.02700"/>
		<axis xyz="0.00000 0.00000 0.00000"/>
	</joint>
	<joint name="jointfix_46_14" type="fixed">
		<parent link="left_leg/foot"/>
		<child link="left_leg/ffp_9_0"/>
		<dynamics damping="1.0" friction="0.0001"/>
		<origin rpy="0.00000 -0.00000 0.00000" xyz="0.11900 -0.04700 -0.02700"/>
		<axis xyz="0.00000 0.00000 0.00000"/>
	</joint>
	<joint name="jointfix_47_14" type="fixed">
		<parent link="left_leg/foot"/>
		<child link="left_leg/ffp_9_1"/>
		<dynamics damping="1.0" friction="0.0001"/>
		<origin rpy="0.00000 -0.00000 0.00000" xyz="0.11900 -0.02540 -0.02700"/>
		<axis xyz="0.00000 0.00000 0.00000"/>
	</joint>
	<joint name="jointfix_48_14" type="fixed">
		<parent link="left_leg/foot"/>
		<child link="left_leg/ffp_9_2"/>
		<dynamics damping="1.0" friction="0.0001"/>
		<origin rpy="0.00000 -0.00000 0.00000" xyz="0.11900 -0.00380 -0.02700"/>
		<axis xyz="0.00000 0.00000 0.00000"/>
	</joint>
	<joint name="jointfix_49_14" type="fixed">
		<parent link="left_leg/foot"/>
		<child link="left_leg/ffp_9_3"/>
		<dynamics damping="1.0" friction="0.0001"/>
		<origin rpy="0.00000 -0.00000 0.00000" xyz="0.11900 0.01780 -0.02700"/>
		<axis xyz="0.00000 0.00000 0.00000"/>
	</joint>
	<joint name="jointfix_50_14" type="fixed">
		<parent link="left_leg/foot"/>
		<child link="left_leg/ffp_9_4"/>
		<dynamics damping="1.0" friction="0.0001"/>
		<origin rpy="0.00000 -0.00000 0.00000" xyz="0.11900 0.03940 -0.02700"/>
		<axis xyz="0.00000 0.00000 0.00000"/>
	</joint>
	<joint name="jointfix_108_5" type="fixed">
		<parent link="pelvis"/>
		<child link="right_leg/"/>
		<dynamics damping="1.0" friction="0.0001"/>
		<origin rpy="0.00000 -0.00000 0.00000" xyz="0.00000 -0.10000 -0.04000"/>
		<axis xyz="0.00000 0.00000 0.00000"/>
	</joint>
	<joint name="right_leg/hip_x" type="revolute">
		<parent link="right_leg/"/>
		<child link="link1_69"/>
		<limit effort="0.00000" lower="-25.00000" upper="5.00000" velocity="0.00000"/>
		<dynamics damping="1.0" friction="0.0001"/>
		<origin rpy="0.00000 -0.00000 0.00000" xyz="0.00000 0.00000 0.00000"/>
		<axis xyz="1.00000 0.00000 0.00000"/>
	</joint>
	<joint name="right_leg/hip_z" type="revolute">
		<parent link="link1_69"/>
		<child link="link1_70"/>
		<limit effort="0.00000" lower="-60.00000" upper="35.00000" velocity="0.00000"/>
		<dynamics damping="1.0" friction="0.0001"/>
		<origin rpy="0.00000 -0.00000 0.00000" xyz="0.00000 0.00000 0.00000"/>
		<axis xyz="0.00000 0.00000 1.00000"/>
	</joint>
	<joint name="right_leg/hip_y" type="revolute">
		<parent link="link1_70"/>
		<child link="link1_71"/>
		<limit effort="0.00000" lower="-110.00000" upper="20.00000" velocity="0.00000"/>
		<dynamics damping="1.0" friction="0.0001"/>
		<origin rpy="0.00000 -0.00000 0.00000" xyz="0.00000 0.00000 0.00000"/>
		<axis xyz="0.00000 1.00000 0.00000"/>
	</joint>
	<joint name="jointfix_107_71" type="fixed">
		<parent link="link1_71"/>
		<child link="right_leg/thigh"/>
		<dynamics damping="1.0" friction="0.0001"/>
		<origin rpy="0.00000 -0.00000 0.00000" xyz="0.00000 0.00000 0.00000"/>
		<axis xyz="0.00000 0.00000 0.00000"/>
	</joint>
	<joint name="right_leg/knee" type="revolute">
		<parent link="right_leg/thigh"/>
		<child link="link1_73"/>
		<limit effort="0.00000" lower="-160.00000" upper="2.00000" velocity="0.00000"/>
		<dynamics damping="1.0" friction="0.0001"/>
		<origin rpy="0.00000 -0.00000 0.00000" xyz="0.00000 0.01000 -0.32300"/>
		<axis xyz="0.00000 -1.00000 0.00000"/>
	</joint>
	<joint name="jointfix_106_73" type="fixed">
		<parent link="link1_73"/>
		<child link="right_leg/shin"/>
		<dynamics damping="1.0" friction="0.0001"/>
		<origin rpy="0.00000 -0.00000 0.00000" xyz="0.00000 0.00000 -0.02000"/>
		<axis xyz="0.00000 0.00000 0.00000"/>
	</joint>
	<joint name="right_leg/ankle_y" type="revolute">
		<parent link="right_leg/shin"/>
		<child link="link1_75"/>
		<limit effort="0.00000" lower="-50.00000" upper="50.00000" velocity="0.00000"/>
		<dynamics damping="1.0" friction="0.0001"/>
		<origin rpy="0.00000 -0.00000 0.00000" xyz="0.00000 0.00000 -0.21200"/>
		<axis xyz="0.00000 1.00000 0.00000"/>
	</joint>
	<joint name="right_leg/ankle_x" type="revolute">
		<parent link="link1_75"/>
		<child link="link1_76"/>
		<limit effort="0.00000" lower="-50.00000" upper="50.00000" velocity="0.00000"/>
		<dynamics damping="1.0" friction="0.0001"/>
		<origin rpy="0.00000 -0.00000 0.00000" xyz="0.00000 0.00000 -0.04000"/>
		<axis xyz="1.00000 0.00000 0.50000"/>
	</joint>
	<joint name="jointfix_105_76" type="fixed">
		<parent link="link1_76"/>
		<child link="right_leg/foot"/>
		<dynamics damping="1.0" friction="0.0001"/>
		<origin rpy="0.00000 -0.00000 0.00000" xyz="0.00000 0.00000 -0.08000"/>
		<axis xyz="0.00000 0.00000 0.00000"/>
	</joint>
	<joint name="jointfix_55_74" type="fixed">
		<parent link="right_leg/foot"/>
		<child link="right_leg/ffp_0_0"/>
		<dynamics damping="1.0" friction="0.0001"/>
		<origin rpy="0.00000 -0.00000 0.00000" xyz="-0.07000 -0.04700 -0.02700"/>
		<axis xyz="0.00000 0.00000 0.00000"/>
	</joint>
	<joint name="jointfix_56_74" type="fixed">
		<parent link="right_leg/foot"/>
		<child link="right_leg/ffp_0_1"/>
		<dynamics damping="1.0" friction="0.0001"/>
		<origin rpy="0.00000 -0.00000 0.00000" xyz="-0.07000 -0.02540 -0.02700"/>
		<axis xyz="0.00000 0.00000 0.00000"/>
	</joint>
	<joint name="jointfix_57_74" type="fixed">
		<parent link="right_leg/foot"/>
		<child link="right_leg/ffp_0_2"/>
		<dynamics damping="1.0" friction="0.0001"/>
		<origin rpy="0.00000 -0.00000 0.00000" xyz="-0.07000 -0.00380 -0.02700"/>
		<axis xyz="0.00000 0.00000 0.00000"/>
	</joint>
	<joint name="jointfix_58_74" type="fixed">
		<parent link="right_leg/foot"/>
		<child link="right_leg/ffp_0_3"/>
		<dynamics damping="1.0" friction="0.0001"/>
		<origin rpy="0.00000 -0.00000 0.00000" xyz="-0.07000 0.01780 -0.02700"/>
		<axis xyz="0.00000 0.00000 0.00000"/>
	</joint>
	<joint name="jointfix_59_74" type="fixed">
		<parent link="right_leg/foot"/>
		<child link="right_leg/ffp_0_4"/>
		<dynamics damping="1.0" friction="0.0001"/>
		<origin rpy="0.00000 -0.00000 0.00000" xyz="-0.07000 0.03940 -0.02700"/>
		<axis xyz="0.00000 0.00000 0.00000"/>
	</joint>
	<joint name="jointfix_60_74" type="fixed">
		<parent link="right_leg/foot"/>
		<child link="right_leg/ffp_1_0"/>
		<dynamics damping="1.0" friction="0.0001"/>
		<origin rpy="0.00000 -0.00000 0.00000" xyz="-0.04900 -0.04700 -0.02700"/>
		<axis xyz="0.00000 0.00000 0.00000"/>
	</joint>
	<joint name="jointfix_61_74" type="fixed">
		<parent link="right_leg/foot"/>
		<child link="right_leg/ffp_1_1"/>
		<dynamics damping="1.0" friction="0.0001"/>
		<origin rpy="0.00000 -0.00000 0.00000" xyz="-0.04900 -0.02540 -0.02700"/>
		<axis xyz="0.00000 0.00000 0.00000"/>
	</joint>
	<joint name="jointfix_62_74" type="fixed">
		<parent link="right_leg/foot"/>
		<child link="right_leg/ffp_1_2"/>
		<dynamics damping="1.0" friction="0.0001"/>
		<origin rpy="0.00000 -0.00000 0.00000" xyz="-0.04900 -0.00380 -0.02700"/>
		<axis xyz="0.00000 0.00000 0.00000"/>
	</joint>
	<joint name="jointfix_63_74" type="fixed">
		<parent link="right_leg/foot"/>
		<child link="right_leg/ffp_1_3"/>
		<dynamics damping="1.0" friction="0.0001"/>
		<origin rpy="0.00000 -0.00000 0.00000" xyz="-0.04900 0.01780 -0.02700"/>
		<axis xyz="0.00000 0.00000 0.00000"/>
	</joint>
	<joint name="jointfix_64_74" type="fixed">
		<parent link="right_leg/foot"/>
		<child link="right_leg/ffp_1_4"/>
		<dynamics damping="1.0" friction="0.0001"/>
		<origin rpy="0.00000 -0.00000 0.00000" xyz="-0.04900 0.03940 -0.02700"/>
		<axis xyz="0.00000 0.00000 0.00000"/>
	</joint>
	<joint name="jointfix_65_74" type="fixed">
		<parent link="right_leg/foot"/>
		<child link="right_leg/ffp_2_0"/>
		<dynamics damping="1.0" friction="0.0001"/>
		<origin rpy="0.00000 -0.00000 0.00000" xyz="-0.02800 -0.04700 -0.02700"/>
		<axis xyz="0.00000 0.00000 0.00000"/>
	</joint>
	<joint name="jointfix_66_74" type="fixed">
		<parent link="right_leg/foot"/>
		<child link="right_leg/ffp_2_1"/>
		<dynamics damping="1.0" friction="0.0001"/>
		<origin rpy="0.00000 -0.00000 0.00000" xyz="-0.02800 -0.02540 -0.02700"/>
		<axis xyz="0.00000 0.00000 0.00000"/>
	</joint>
	<joint name="jointfix_67_74" type="fixed">
		<parent link="right_leg/foot"/>
		<child link="right_leg/ffp_2_2"/>
		<dynamics damping="1.0" friction="0.0001"/>
		<origin rpy="0.00000 -0.00000 0.00000" xyz="-0.02800 -0.00380 -0.02700"/>
		<axis xyz="0.00000 0.00000 0.00000"/>
	</joint>
	<joint name="jointfix_68_74" type="fixed">
		<parent link="right_leg/foot"/>
		<child link="right_leg/ffp_2_3"/>
		<dynamics damping="1.0" friction="0.0001"/>
		<origin rpy="0.00000 -0.00000 0.00000" xyz="-0.02800 0.01780 -0.02700"/>
		<axis xyz="0.00000 0.00000 0.00000"/>
	</joint>
	<joint name="jointfix_69_74" type="fixed">
		<parent link="right_leg/foot"/>
		<child link="right_leg/ffp_2_4"/>
		<dynamics damping="1.0" friction="0.0001"/>
		<origin rpy="0.00000 -0.00000 0.00000" xyz="-0.02800 0.03940 -0.02700"/>
		<axis xyz="0.00000 0.00000 0.00000"/>
	</joint>
	<joint name="jointfix_70_74" type="fixed">
		<parent link="right_leg/foot"/>
		<child link="right_leg/ffp_3_0"/>
		<dynamics damping="1.0" friction="0.0001"/>
		<origin rpy="0.00000 -0.00000 0.00000" xyz="-0.00700 -0.04700 -0.02700"/>
		<axis xyz="0.00000 0.00000 0.00000"/>
	</joint>
	<joint name="jointfix_71_74" type="fixed">
		<parent link="right_leg/foot"/>
		<child link="right_leg/ffp_3_1"/>
		<dynamics damping="1.0" friction="0.0001"/>
		<origin rpy="0.00000 -0.00000 0.00000" xyz="-0.00700 -0.02540 -0.02700"/>
		<axis xyz="0.00000 0.00000 0.00000"/>
	</joint>
	<joint name="jointfix_72_74" type="fixed">
		<parent link="right_leg/foot"/>
		<child link="right_leg/ffp_3_2"/>
		<dynamics damping="1.0" friction="0.0001"/>
		<origin rpy="0.00000 -0.00000 0.00000" xyz="-0.00700 -0.00380 -0.02700"/>
		<axis xyz="0.00000 0.00000 0.00000"/>
	</joint>
	<joint name="jointfix_73_74" type="fixed">
		<parent link="right_leg/foot"/>
		<child link="right_leg/ffp_3_3"/>
		<dynamics damping="1.0" friction="0.0001"/>
		<origin rpy="0.00000 -0.00000 0.00000" xyz="-0.00700 0.01780 -0.02700"/>
		<axis xyz="0.00000 0.00000 0.00000"/>
	</joint>
	<joint name="jointfix_74_74" type="fixed">
		<parent link="right_leg/foot"/>
		<child link="right_leg/ffp_3_4"/>
		<dynamics damping="1.0" friction="0.0001"/>
		<origin rpy="0.00000 -0.00000 0.00000" xyz="-0.00700 0.03940 -0.02700"/>
		<axis xyz="0.00000 0.00000 0.00000"/>
	</joint>
	<joint name="jointfix_75_74" type="fixed">
		<parent link="right_leg/foot"/>
		<child link="right_leg/ffp_4_0"/>
		<dynamics damping="1.0" friction="0.0001"/>
		<origin rpy="0.00000 -0.00000 0.00000" xyz="0.01400 -0.04700 -0.02700"/>
		<axis xyz="0.00000 0.00000 0.00000"/>
	</joint>
	<joint name="jointfix_76_74" type="fixed">
		<parent link="right_leg/foot"/>
		<child link="right_leg/ffp_4_1"/>
		<dynamics damping="1.0" friction="0.0001"/>
		<origin rpy="0.00000 -0.00000 0.00000" xyz="0.01400 -0.02540 -0.02700"/>
		<axis xyz="0.00000 0.00000 0.00000"/>
	</joint>
	<joint name="jointfix_77_74" type="fixed">
		<parent link="right_leg/foot"/>
		<child link="right_leg/ffp_4_2"/>
		<dynamics damping="1.0" friction="0.0001"/>
		<origin rpy="0.00000 -0.00000 0.00000" xyz="0.01400 -0.00380 -0.02700"/>
		<axis xyz="0.00000 0.00000 0.00000"/>
	</joint>
	<joint name="jointfix_78_74" type="fixed">
		<parent link="right_leg/foot"/>
		<child link="right_leg/ffp_4_3"/>
		<dynamics damping="1.0" friction="0.0001"/>
		<origin rpy="0.00000 -0.00000 0.00000" xyz="0.01400 0.01780 -0.02700"/>
		<axis xyz="0.00000 0.00000 0.00000"/>
	</joint>
	<joint name="jointfix_79_74" type="fixed">
		<parent link="right_leg/foot"/>
		<child link="right_leg/ffp_4_4"/>
		<dynamics damping="1.0" friction="0.0001"/>
		<origin rpy="0.00000 -0.00000 0.00000" xyz="0.01400 0.03940 -0.02700"/>
		<axis xyz="0.00000 0.00000 0.00000"/>
	</joint>
	<joint name="jointfix_80_74" type="fixed">
		<parent link="right_leg/foot"/>
		<child link="right_leg/ffp_5_0"/>
		<dynamics damping="1.0" friction="0.0001"/>
		<origin rpy="0.00000 -0.00000 0.00000" xyz="0.03500 -0.04700 -0.02700"/>
		<axis xyz="0.00000 0.00000 0.00000"/>
	</joint>
	<joint name="jointfix_81_74" type="fixed">
		<parent link="right_leg/foot"/>
		<child link="right_leg/ffp_5_1"/>
		<dynamics damping="1.0" friction="0.0001"/>
		<origin rpy="0.00000 -0.00000 0.00000" xyz="0.03500 -0.02540 -0.02700"/>
		<axis xyz="0.00000 0.00000 0.00000"/>
	</joint>
	<joint name="jointfix_82_74" type="fixed">
		<parent link="right_leg/foot"/>
		<child link="right_leg/ffp_5_2"/>
		<dynamics damping="1.0" friction="0.0001"/>
		<origin rpy="0.00000 -0.00000 0.00000" xyz="0.03500 -0.00380 -0.02700"/>
		<axis xyz="0.00000 0.00000 0.00000"/>
	</joint>
	<joint name="jointfix_83_74" type="fixed">
		<parent link="right_leg/foot"/>
		<child link="right_leg/ffp_5_3"/>
		<dynamics damping="1.0" friction="0.0001"/>
		<origin rpy="0.00000 -0.00000 0.00000" xyz="0.03500 0.01780 -0.02700"/>
		<axis xyz="0.00000 0.00000 0.00000"/>
	</joint>
	<joint name="jointfix_84_74" type="fixed">
		<parent link="right_leg/foot"/>
		<child link="right_leg/ffp_5_4"/>
		<dynamics damping="1.0" friction="0.0001"/>
		<origin rpy="0.00000 -0.00000 0.00000" xyz="0.03500 0.03940 -0.02700"/>
		<axis xyz="0.00000 0.00000 0.00000"/>
	</joint>
	<joint name="jointfix_85_74" type="fixed">
		<parent link="right_leg/foot"/>
		<child link="right_leg/ffp_6_0"/>
		<dynamics damping="1.0" friction="0.0001"/>
		<origin rpy="0.00000 -0.00000 0.00000" xyz="0.05600 -0.04700 -0.02700"/>
		<axis xyz="0.00000 0.00000 0.00000"/>
	</joint>
	<joint name="jointfix_86_74" type="fixed">
		<parent link="right_leg/foot"/>
		<child link="right_leg/ffp_6_1"/>
		<dynamics damping="1.0" friction="0.0001"/>
		<origin rpy="0.00000 -0.00000 0.00000" xyz="0.05600 -0.02540 -0.02700"/>
		<axis xyz="0.00000 0.00000 0.00000"/>
	</joint>
	<joint name="jointfix_87_74" type="fixed">
		<parent link="right_leg/foot"/>
		<child link="right_leg/ffp_6_2"/>
		<dynamics damping="1.0" friction="0.0001"/>
		<origin rpy="0.00000 -0.00000 0.00000" xyz="0.05600 -0.00380 -0.02700"/>
		<axis xyz="0.00000 0.00000 0.00000"/>
	</joint>
	<joint name="jointfix_88_74" type="fixed">
		<parent link="right_leg/foot"/>
		<child link="right_leg/ffp_6_3"/>
		<dynamics damping="1.0" friction="0.0001"/>
		<origin rpy="0.00000 -0.00000 0.00000" xyz="0.05600 0.01780 -0.02700"/>
		<axis xyz="0.00000 0.00000 0.00000"/>
	</joint>
	<joint name="jointfix_89_74" type="fixed">
		<parent link="right_leg/foot"/>
		<child link="right_leg/ffp_6_4"/>
		<dynamics damping="1.0" friction="0.0001"/>
		<origin rpy="0.00000 -0.00000 0.00000" xyz="0.05600 0.03940 -0.02700"/>
		<axis xyz="0.00000 0.00000 0.00000"/>
	</joint>
	<joint name="jointfix_90_74" type="fixed">
		<parent link="right_leg/foot"/>
		<child link="right_leg/ffp_7_0"/>
		<dynamics damping="1.0" friction="0.0001"/>
		<origin rpy="0.00000 -0.00000 0.00000" xyz="0.07700 -0.04700 -0.02700"/>
		<axis xyz="0.00000 0.00000 0.00000"/>
	</joint>
	<joint name="jointfix_91_74" type="fixed">
		<parent link="right_leg/foot"/>
		<child link="right_leg/ffp_7_1"/>
		<dynamics damping="1.0" friction="0.0001"/>
		<origin rpy="0.00000 -0.00000 0.00000" xyz="0.07700 -0.02540 -0.02700"/>
		<axis xyz="0.00000 0.00000 0.00000"/>
	</joint>
	<joint name="jointfix_92_74" type="fixed">
		<parent link="right_leg/foot"/>
		<child link="right_leg/ffp_7_2"/>
		<dynamics damping="1.0" friction="0.0001"/>
		<origin rpy="0.00000 -0.00000 0.00000" xyz="0.07700 -0.00380 -0.02700"/>
		<axis xyz="0.00000 0.00000 0.00000"/>
	</joint>
	<joint name="jointfix_93_74" type="fixed">
		<parent link="right_leg/foot"/>
		<child link="right_leg/ffp_7_3"/>
		<dynamics damping="1.0" friction="0.0001"/>
		<origin rpy="0.00000 -0.00000 0.00000" xyz="0.07700 0.01780 -0.02700"/>
		<axis xyz="0.00000 0.00000 0.00000"/>
	</joint>
	<joint name="jointfix_94_74" type="fixed">
		<parent link="right_leg/foot"/>
		<child link="right_leg/ffp_7_4"/>
		<dynamics damping="1.0" friction="0.0001"/>
		<origin rpy="0.00000 -0.00000 0.00000" xyz="0.07700 0.03940 -0.02700"/>
		<axis xyz="0.00000 0.00000 0.00000"/>
	</joint>
	<joint name="jointfix_95_74" type="fixed">
		<parent link="right_leg/foot"/>
		<child link="right_leg/ffp_8_0"/>
		<dynamics damping="1.0" friction="0.0001"/>
		<origin rpy="0.00000 -0.00000 0.00000" xyz="0.09800 -0.04700 -0.02700"/>
		<axis xyz="0.00000 0.00000 0.00000"/>
	</joint>
	<joint name="jointfix_96_74" type="fixed">
		<parent link="right_leg/foot"/>
		<child link="right_leg/ffp_8_1"/>
		<dynamics damping="1.0" friction="0.0001"/>
		<origin rpy="0.00000 -0.00000 0.00000" xyz="0.09800 -0.02540 -0.02700"/>
		<axis xyz="0.00000 0.00000 0.00000"/>
	</joint>
	<joint name="jointfix_97_74" type="fixed">
		<parent link="right_leg/foot"/>
		<child link="right_leg/ffp_8_2"/>
		<dynamics damping="1.0" friction="0.0001"/>
		<origin rpy="0.00000 -0.00000 0.00000" xyz="0.09800 -0.00380 -0.02700"/>
		<axis xyz="0.00000 0.00000 0.00000"/>
	</joint>
	<joint name="jointfix_98_74" type="fixed">
		<parent link="right_leg/foot"/>
		<child link="right_leg/ffp_8_3"/>
		<dynamics damping="1.0" friction="0.0001"/>
		<origin rpy="0.00000 -0.00000 0.00000" xyz="0.09800 0.01780 -0.02700"/>
		<axis xyz="0.00000 0.00000 0.00000"/>
	</joint>
	<joint name="jointfix_99_74" type="fixed">
		<parent link="right_leg/foot"/>
		<child link="right_leg/ffp_8_4"/>
		<dynamics damping="1.0" friction="0.0001"/>
		<origin rpy="0.00000 -0.00000 0.00000" xyz="0.09800 0.03940 -0.02700"/>
		<axis xyz="0.00000 0.00000 0.00000"/>
	</joint>
	<joint name="jointfix_100_74" type="fixed">
		<parent link="right_leg/foot"/>
		<child link="right_leg/ffp_9_0"/>
		<dynamics damping="1.0" friction="0.0001"/>
		<origin rpy="0.00000 -0.00000 0.00000" xyz="0.11900 -0.04700 -0.02700"/>
		<axis xyz="0.00000 0.00000 0.00000"/>
	</joint>
	<joint name="jointfix_101_74" type="fixed">
		<parent link="right_leg/foot"/>
		<child link="right_leg/ffp_9_1"/>
		<dynamics damping="1.0" friction="0.0001"/>
		<origin rpy="0.00000 -0.00000 0.00000" xyz="0.11900 -0.02540 -0.02700"/>
		<axis xyz="0.00000 0.00000 0.00000"/>
	</joint>
	<joint name="jointfix_102_74" type="fixed">
		<parent link="right_leg/foot"/>
		<child link="right_leg/ffp_9_2"/>
		<dynamics damping="1.0" friction="0.0001"/>
		<origin rpy="0.00000 -0.00000 0.00000" xyz="0.11900 -0.00380 -0.02700"/>
		<axis xyz="0.00000 0.00000 0.00000"/>
	</joint>
	<joint name="jointfix_103_74" type="fixed">
		<parent link="right_leg/foot"/>
		<child link="right_leg/ffp_9_3"/>
		<dynamics damping="1.0" friction="0.0001"/>
		<origin rpy="0.00000 -0.00000 0.00000" xyz="0.11900 0.01780 -0.02700"/>
		<axis xyz="0.00000 0.00000 0.00000"/>
	</joint>
	<joint name="jointfix_104_74" type="fixed">
		<parent link="right_leg/foot"/>
		<child link="right_leg/ffp_9_4"/>
		<dynamics damping="1.0" friction="0.0001"/>
		<origin rpy="0.00000 -0.00000 0.00000" xyz="0.11900 0.03940 -0.02700"/>
		<axis xyz="0.00000 0.00000 0.00000"/>
	</joint>
</robot>
